Workbook

Sheet Master
F1: 전체 현황
E23: 1월 | K23: 2월 | P23: 3월 | V23: 4월 | AB23: 5월 | AI23: 6월 | AO23: 7월 | AU23: 8월 | BB23: 9월 | BH23: 10월 | BN23: 11월 | BT23: 12월
E24: 실적 | F24: W1 | G24: W2 | H24: W3 | I24: W4 | J24: W5 | K24: 실적 | L24: W6 | M24: W7 | N24: W8 | O24: W9 | P24: 실적 | Q24: W10 | R24: W11 | S24: W12 | T24: W13 | U24: W14 | V24: 실적 | W24: W14 | X24: W15 | Y24: W16 | Z24: W17 | AA24: W18 | AB24: 실적 | AC24: W18 | AD24: W19 | AE24: W20 | AF24: W21 | AG24: W22 | AH24: W23 | AI24: 실적 | AJ24: W23 | AK24: W24 | AL24: W25 | AM24: W26 | AN24: W27 | AO24: 실적 | AP24: W27 | AQ24: W28 | AR24: W29 | AS24: W30 | AT24: W31 | AU24: 실적 | AV24: W31 | AW24: W32 | AX24: W33 | AY24: W34 | AZ24: W35 | BA24: W36 | BB24: 실적 | BC24: W36 | BD24: W37 | BE24: W38 | BF24: W39 | BG24: W40 | BH24: 실적 | BI24: W40 | BJ24: W41 | BK24: W42 | BL24: W43 | BM24: W44 | BN24: 실적 | BO24: W45 | BP24: W46 | BQ24: W47 | BR24: W48 | BS24: W49 | BT24: 실적 | BU24: W49 | BV24: W50 | BW24: W51 | BX24: W52 | BY24: W53
B25: 합계 | D25: 목표 | E25: =SUM(E31,E33,E35,E37,E39,E41,E43,E45,E47,E49) | F25: =SUM(F31,F33,F35,F37,F39,F41,F43,F45,F47,F49) | G25: =SUM(G31,G33,G35,G37,G39,G41,G43,G45,G47,G49) | H25: =SUM(H31,H33,H35,H37,H39,H41,H43,H45,H47,H49) | I25: =SUM(I31,I33,I35,I37,I39,I41,I43,I45,I47,I49) | J25: =SUM(J31,J33,J35,J37,J39,J41,J43,J45,J47,J49) | K25: =SUM(K31,K33,K35,K37,K39,K41,K43,K45,K47,K49) | L25: =SUM(L31,L33,L35,L37,L39,L41,L43,L45,L47,L49) | ... AA25: =SUM(AA31,AA33,AA35,AA37,AA39,AA41,AA43,AA45,AA47,AA49)
D26: 실적 | E26: =SUM(E32,E34,E36,E38,E40,E42,E44,E46,E48,E50) | F26: =SUM(F32,F34,F36,F38,F40,F42,F44,F46,F48,F50) | G26: =SUM(G32,G34,G36,G38,G40,G42,G44,G46,G48,G50) | H26: =SUM(H32,H34,H36,H38,H40,H42,H44,H46,H48,H50) | I26: =SUM(I32,I34,I36,I38,I40,I42,I44,I46,I48,I50) | J26: =SUM(J32,J34,J36,J38,J40,J42,J44,J46,J48,J50) | K26: =SUM(K32,K34,K36,K38,K40,K42,K44,K46,K48,K50) | L26: =SUM(L32,L34,L36,L38,L40,L42,L44,L46,L48,L50) | ... AA26: =SUM(AA32,AA34,AA36,AA38,AA40,AA42,AA44,AA46,AA48,AA50)
D27: 달성율 | E27: =E26/E25 | F27: =F26/F25 | G27: =G26/G25 | H27: =H26/H25 | I27: =I26/I25 | J27: =J26/J25 | K27: =K26/K25 | L27: =L26/L25 | ... AA27: =AA26/AA25
B28: 합계 (고정비 제외) | D28: 목표 | E28: =SUM(E31,E33,E35,E37,E39,E41,E43,E45,E47) | F28: =SUM(F31,F33,F35,F37,F39,F41,F43,F45,F47) | G28: =SUM(G31,G33,G35,G37,G39,G41,G43,G45,G47) | H28: =SUM(H31,H33,H35,H37,H39,H41,H43,H45,H47) | I28: =SUM(I31,I33,I35,I37,I39,I41,I43,I45,I47) | J28: =SUM(J31,J33,J35,J37,J39,J41,J43,J45,J47) | K28: =SUM(K31,K33,K35,K37,K39,K41,K43,K45,K47) | L28: =SUM(L31,L33,L35,L37,L39,L41,L43,L45,L47) | ... AA28: =SUM(AA31,AA33,AA35,AA37,AA39,AA41,AA43,AA45,AA47)
D29: 실적 | E29: =SUM(E32,E34,E36,E38,E40,E42,E44,E46,E48) | F29: =SUM(F32,F34,F36,F38,F40,F42,F44,F46,F48) | G29: =SUM(G32,G34,G36,G38,G40,G42,G44,G46,G48) | H29: =SUM(H32,H34,H36,H38,H40,H42,H44,H46,H48) | I29: =SUM(I32,I34,I36,I38,I40,I42,I44,I46,I48) | J29: =SUM(J32,J34,J36,J38,J40,J42,J44,J46,J48) | K29: =SUM(K32,K34,K36,K38,K40,K42,K44,K46,K48) | L29: =SUM(L32,L34,L36,L38,L40,L42,L44,L46,L48) | ... AA29: =SUM(AA32,AA34,AA36,AA38,AA40,AA42,AA44,AA46,AA48)
D30: 달성율 | E30: =E29/E28 | F30: =F29/F28 | G30: =G29/G28 | H30: =H29/H28 | I30: =I29/I28 | J30: =J29/J28 | K30: =K29/K28 | L30: =L29/L28 | ... AA30: =AA29/AA28
B31: 재료비 | C31: 시스템 반영 VI | D31: 목표 | E31: =재료비!G24 | F31: =재료비!H24 | G31: =재료비!I24 | H31: =재료비!J24 | I31: =재료비!K24 | J31: =재료비!L24 | K31: =재료비!M24 | L31: =재료비!N24 | ... AA31: =재료비!AC24
D32: 실적 | E32: =재료비!G25 | F32: =재료비!H25 | G32: =재료비!I25 | H32: =재료비!J25 | I32: =재료비!K25 | J32: =재료비!L25 | K32: =재료비!M25 | L32: =재료비!N25 | ... AA32: =재료비!AC25
C33: 시스템 미반영 VI | D33: 목표 | E33: =재료비!G36 | F33: =재료비!H36 | G33: =재료비!I36 | H33: =재료비!J36 | I33: =재료비!K36 | J33: =재료비!L36 | K33: =재료비!M36 | L33: =재료비!N36 | ... AA33: =재료비!AC36
D34: 실적 | E34: =재료비!G37 | F34: =재료비!H37 | G34: =재료비!I37 | H34: =재료비!J37 | I34: =재료비!K37 | J34: =재료비!L37 | K34: =재료비!M37 | L34: =재료비!N37 | ... AA34: =재료비!AC37
B35: 가공비 | D35: 목표 | E35: =가공비!G6 | F35: =가공비!H6 | G35: =가공비!I6 | H35: =가공비!J6 | I35: =가공비!K6 | J35: =가공비!L6 | K35: =가공비!M6 | L35: =가공비!N6 | ... AA35: =가공비!AC6
D36: 실적 | E36: =가공비!G7 | F36: =가공비!H7 | G36: =가공비!I7 | H36: =가공비!J7 | I36: =가공비!K7 | J36: =가공비!L7 | K36: =가공비!M7 | L36: =가공비!N7 | ... AA36: =가공비!AC7
B37: 물류비 | D37: 목표 | E37: =물류비!E9 | F37: =물류비!F9 | G37: =물류비!G9 | H37: =물류비!H9 | I37: =물류비!I9 | J37: =물류비!J9 | K37: =물류비!K9 | L37: =물류비!L9 | ... AA37: =물류비!AA9
D38: 실적 | E38: =물류비!E10 | F38: =물류비!F10 | G38: =물류비!G10 | H38: =물류비!H10 | I38: =물류비!I10 | J38: =물류비!J10 | K38: =물류비!K10 | L38: =물류비!L10 | ... AA38: =물류비!AA10
B39: 투자비 | C39: 설비 | D39: 목표 | E39: =투자비!F8 | F39: =투자비!G8 | G39: =투자비!H8 | H39: =투자비!I8 | I39: =투자비!J8 | J39: =투자비!K8 | K39: =투자비!L8 | L39: =투자비!M8 | ... AA39: =투자비!AB8
D40: 실적 | E40: =투자비!F12 | F40: =투자비!G12 | G40: =투자비!H12 | H40: =투자비!I12 | I40: =투자비!J12 | J40: =투자비!K12 | K40: =투자비!L12 | L40: =투자비!M12 | ... AA40: =투자비!AB12
C41: 금형 | D41: 목표 | E41: =투자비!F16 | F41: =투자비!G16 | G41: =투자비!H16 | H41: =투자비!I16 | I41: =투자비!J16 | J41: =투자비!K16 | K41: =투자비!L16 | L41: =투자비!M16 | ... AA41: =투자비!AB16
D42: 실적 | E42: =투자비!F20 | F42: =투자비!G20 | G42: =투자비!H20 | H42: =투자비!I20 | I42: =투자비!J20 | J42: =투자비!K20 | K42: =투자비!L20 | L42: =투자비!M20 | ... AA42: =투자비!AB20
B43: 매출 | C43: 지역1 | D43: 목표 | E43: =매출_지역1!E5 | F43: =매출_지역1!F5 | G43: =매출_지역1!G5 | H43: =매출_지역1!H5 | I43: =매출_지역1!I5 | J43: =매출_지역1!J5 | K43: =매출_지역1!K5 | L43: =매출_지역1!L5 | ... AA43: =매출_지역1!AA5
D44: 실적 | E44: =매출_지역1!E6 | F44: =매출_지역1!F6 | G44: =매출_지역1!G6 | H44: =매출_지역1!H6 | I44: =매출_지역1!I6 | J44: =매출_지역1!J6 | K44: =매출_지역1!K6 | L44: =매출_지역1!L6 | ... AA44: =매출_지역1!AA6
C45: 지역2 | D45: 목표 | E45: =매출_지역2!F15 | K45: =매출_지역2!G15 | P45: =매출_지역2!H15 | V45: =매출_지역2!I15
D46: 실적 | E46: =매출_지역2!F20 | K46: =매출_지역2!G20 | P46: =매출_지역2!H20 | V46: =매출_지역2!I20
B47: 품질 | D47: 목표 | E47: =품질!E4 | F47: =품질!F4 | G47: =품질!G4 | H47: =품질!H4 | I47: =품질!I4 | J47: =품질!J4 | K47: =품질!K4 | L47: =품질!L4 | ... AA47: =품질!AA4
D48: 실적 | E48: =품질!E5 | F48: =품질!F5 | G48: =품질!G5 | H48: =품질!H5 | I48: =품질!I5 | J48: =품질!J5 | K48: =품질!K5 | L48: =품질!L5 | ... AA48: =품질!AA5
B49: 고정비 | D49: 목표 | E49: =고정비!G6 | K49: =고정비!H6 | P49: =고정비!I6 | V49: =고정비!J6
D50: 실적 | E50: =고정비!G7 | K50: =고정비!H7 | P50: =고정비!I7 | V50: =고정비!J7
E51: 주차별 실적이 없는 경우 월별 실적으로 기입
B56: Master Graph 전체 현황 로직 : 월별 실적의 누적값 | E56: 1월 | F56: 2월 | G56: 3월 | H56: 4월 | I56: 5월 | J56: 6월 | K56: 7월 | L56: 8월 | M56: 9월 | N56: 10월 | O56: 11월 | P56: 12월
B57: 합계 | D57: 목표 | E57: =E25 | F57: =E57+K25 | G57: =F57+P25 | H57: =G57+V25
D58: 실적 | E58: =E26 | F58: =E58+K26 | G58: =F58+P26 | H58: =G58+V26
D59: 달성율 | E59: =E58/E57 | F59: =F58/F57 | G59: =G58/G57 | H59: =H58/H57
B60: 합계 (고정비 제외) | D60: 목표 | E60: =E28 | F60: =E60+K28 | G60: =F60+P28 | H60: =G60+V28
D61: 실적 | E61: =E29 | F61: =E61+K29 | G61: =F61+P29 | H61: =G61+V29
D62: 달성율 | E62: =E61/E60 | F62: =F61/F60 | G62: =G61/G60 | H62: =H61/H60
B63: 재료비 | C63: 시스템 반영 VI | D63: 목표 | E63: =E31 | F63: =E63+K31 | G63: =F63+P31 | H63: =G63+V31
D64: 실적 | E64: =E32 | F64: =E64+K32 | G64: =F64+P32 | H64: =G64+V32
C65: 시스템 미반영 VI | D65: 목표 | E65: =E33 | F65: =E65+K33 | G65: =F65+P33 | H65: =G65+V33
...

Sheet 재료비
G2: 1월 | M2: 2월 | R2: 3월 | X2: 4월 | AD2: 5월 | AK2: 6월 | AQ2: 7월 | AW2: 8월 | BD2: 9월 | BJ2: 10월 | BP2: 11월 | BV2: 12월
G3: 실적 | H3: W1 | I3: W2 | J3: W3 | K3: W4 | L3: W5 | M3: 실적 | N3: W6 | O3: W7 | P3: W8 | Q3: W9 | R3: 실적 | S3: W10 | T3: W11 | U3: W12 | V3: W13 | W3: W14 | X3: 실적 | Y3: W14 | Z3: W15 | AA3: W16 | AB3: W17 | AC3: W18 | AD3: 실적 | AE3: W18 | AF3: W19 | AG3: W20 | AH3: W21 | AI3: W22 | AJ3: W23 | AK3: 실적 | AL3: W23 | AM3: W24 | AN3: W25 | AO3: W26 | AP3: W27 | AQ3: 실적 | AR3: W27 | AS3: W28 | AT3: W29 | AU3: W30 | AV3: W31 | AW3: 실적 | AX3: W31 | AY3: W32 | AZ3: W33 | BA3: W34 | BB3: W35 | BC3: W36 | BD3: 실적 | BE3: W36 | BF3: W37 | BG3: W38 | BH3: W39 | BI3: W40 | BJ3: 실적 | BK3: W40 | BL3: W41 | BM3: W42 | BN3: W43 | BO3: W44 | BP3: 실적 | BQ3: W45 | BR3: W46 | BS3: W47 | BT3: W48 | BU3: W49 | BV3: 실적 | BW3: W49 | BX3: W50 | BY3: W51 | BZ3: W52 | CA3: W53
B4: RMC | C4: 키친솔루션 | F4: 목표 | G4: =SUM(G6,G8) | H4: =SUM(H6,H8) | I4: =SUM(I6,I8) | J4: =SUM(J6,J8) | K4: =SUM(K6,K8) | L4: =SUM(L6,L8) | M4: =SUM(M6,M8) | N4: =SUM(N6,N8) | ... R4: =SUM(R6,R8) | S4: 6565.6378 | T4: 6565.6378 | U4: 6565.6378 | V4: 6565.6378 | W4: 6565.6378 | X4: =SUM(X6,X8) | Y4: =SUM(Y6,Y8) | Z4: =SUM(Z6,Z8) | AA4: =SUM(AA6,AA8) | AB4: =SUM(AB6,AB8) | AC4: =SUM(AC6,AC8)
F5: 실적 | G5: =SUM(G7,G9) | H5: =SUM(H7,H9) | I5: =SUM(I7,I9) | J5: =SUM(J7,J9) | K5: =SUM(K7,K9) | L5: =SUM(L7,L9) | M5: =SUM(M7,M9) | N5: =SUM(N7,N9) | ... AC5: =SUM(AC7,AC9)
C6: 제품1 | F6: 목표 | G6: 8271.3601 | H6: 8271.3601 | I6: 8271.3601 | J6: 8271.3601 | K6: 8271.3601 | L6: 8271.3601 | M6: 4756.5913 | N6: 4756.5913 | O6: 4756.5913 | P6: 4756.5913 | Q6: 4756.5913 | R6: 3783.3085 | S6: 3783.3085 | T6: 3783.3085 | U6: 3783.3085 | V6: 3783.3085 | W6: 3783.3085 | X6: 6751.0414 | Y6: 6751.0414 | Z6: 6751.0414 | AA6: 6751.0414 | AB6: 6751.0414 | AC6: 6751.0414
F7: 실적 | G7: 7757.9174 | H7: 4144.75 | I7: 4144.75 | J7: 4359.0914 | K7: 4359.0914 | L7: 4144.75 | M7: 6377.869 | N7: 6084.204 | O7: 3742.1053 | P7: 3992.697 | Q7: 2976.1789 | R7: 5624.3521 | S7: 5000.7912 | T7: 4959.6125 | U7: 3090.0487 | V7: 3623.1 | W7: 3623.1 | X7: 3311.2371 | Y7: 3501.8317 | Z7: 5852.0309 | AA7: 5852.0309 | AB7: 6465.2812 | AC7: 5852.0309
C8: 제품2 | F8: 목표 | G8: 171.84919 | H8: 171.84919 | I8: 171.84919 | J8: 171.84919 | K8: 171.84919 | L8: 171.84919 | M8: 301.54407 | N8: 301.54407 | O8: 301.54407 | P8: 301.54407 | Q8: 301.54407 | R8: 231.9011 | S8: 231.9011 | T8: 231.9011 | U8: 231.9011 | V8: 231.9011 | W8: 231.9011 | X8: 172.03312 | Y8: 172.03312 | Z8: 172.03312 | AA8: 172.03312 | AB8: 172.03312 | AC8: 172.03312
F9: 실적 | G9: 286.09105 | H9: 231.57463 | I9: 231.57463 | J9: 225.01377 | K9: 225.01377 | L9: 231.57463 | M9: 228.67594 | N9: 389.235 | O9: 293.84827 | P9: 135.781 | Q9: 228.38325 | R9: 262.50084 | S9: 300.05185 | T9: 337.66501 | U9: 240.23327 | V9: 364.217 | W9: 344.26431 | X9: 277.22833 | Y9: 237.65887 | Z9: 373.82959 | AA9: 373.82959 | AB9: 460.53877 | AC9: 373.82959
B10: 시스템 반영 + 시스템 미반영 | C10: 키친솔루션 | D10: VI율 | F10: 목표 | G10: =G12/G4 | H10: =H12/H4 | I10: =I12/I4 | J10: =J12/J4 | K10: =K12/K4 | L10: =L12/L4 | M10: =M12/M4 | N10: =N12/N4 | ... AC10: =AC12/AC4
F11: 실적 | G11: =G13/G5 | H11: =H13/H5 | I11: =I13/I5 | J11: =J13/J5 | K11: =K13/K5 | L11: =L13/L5 | M11: =M13/M5 | N11: =N13/N5 | ... AC11: =AC13/AC5
D12: VI 금액 | F12: 목표 | G12: =SUM(G16,G20) | H12: =SUM(H16,H20) | I12: =SUM(I16,I20) | J12: =SUM(J16,J20) | K12: =SUM(K16,K20) | L12: =SUM(L16,L20) | M12: =SUM(M16,M20) | N12: =SUM(N16,N20) | ... AC12: =SUM(AC16,AC20)
F13: 실적 | G13: =SUM(G17,G21) | H13: =SUM(H17,H21) | I13: =SUM(I17,I21) | J13: =SUM(J17,J21) | K13: =SUM(K17,K21) | L13: =SUM(L17,L21) | M13: =SUM(M17,M21) | N13: =SUM(N17,N21) | ... AC13: =SUM(AC17,AC21)
C14: 제품1 | D14: VI율 | F14: 목표 | G14: =G16/G6 | H14: =H16/H6 | I14: =I16/I6 | J14: =J16/J6 | K14: =K16/K6 | L14: =L16/L6 | M14: =M16/M6 | N14: =N16/N6 | ... AC14: =AC16/AC6
F15: 실적 | G15: =G17/G7 | H15: =H17/H7 | I15: =I17/I7 | J15: =J17/J7 | K15: =K17/K7 | L15: =L17/L7 | M15: =M17/M7 | N15: =N17/N7 | ... AC15: =AC17/AC7
D16: VI 금액 | F16: 목표 | G16: =SUM(G28,G46) | H16: =SUM(H28,H46) | I16: =SUM(I28,I46) | J16: =SUM(J28,J46) | K16: =SUM(K28,K46) | L16: =SUM(L28,L46) | M16: =SUM(M28,M46) | N16: =SUM(N28,N46) | ... AC16: =SUM(AC28,AC46) | AW16: =SUM(AW18,AW20)
F17: 실적 | G17: =SUM(G29,G47) | H17: =SUM(H29,H47) | I17: =SUM(I29,I47) | J17: =SUM(J29,J47) | K17: =SUM(K29,K47) | L17: =SUM(L29,L47) | M17: =SUM(M29,M47) | N17: =SUM(N29,N47) | ... AC17: =SUM(AC29,AC47)
C18: 제품2 | D18: VI율 | F18: 목표 | G18: =G20/G8 | H18: =H20/H8 | I18: =I20/I8 | J18: =J20/J8 | K18: =K20/K8 | L18: =L20/L8 | M18: =M20/M8 | N18: =N20/N8 | ... AC18: =AC20/AC8
F19: 실적 | G19: =G21/G9 | H19: =H21/H9 | I19: =I21/I9 | J19: =J21/J9 | K19: =K21/K9 | L19: =L21/L9 | M19: =M21/M9 | N19: =N21/N9 | ... AC19: =AC21/AC9
D20: VI 금액 | F20: 목표 | G20: =SUM(G32,G56) | H20: =SUM(H32,H56) | I20: =SUM(I32,I56) | J20: =SUM(J32,J56) | K20: =SUM(K32,K56) | L20: =SUM(L32,L56) | M20: =SUM(M32,M56) | N20: =SUM(N32,N56) | ... AC20: =SUM(AC32,AC56)
F21: 실적 | G21: =SUM(G33,G57) | H21: =SUM(H33,H57) | I21: =SUM(I33,I57) | J21: =SUM(J33,J57) | K21: =SUM(K33,K57) | L21: =SUM(L33,L57) | M21: =SUM(M33,M57) | N21: =SUM(N33,N57) | ... AC21: =SUM(AC33,AC57)
B22: 시스템 반영 | C22: 키친솔루션 | D22: VI율 | F22: 목표 | G22: =G24/G4 | H22: =H24/H4 | I22: =I24/I4 | J22: =J24/J4 | K22: =K24/K4 | L22: =L24/L4 | M22: =M24/M4 | N22: =N24/N4 | ... AC22: =AC24/AC4
F23: 실적 | G23: =G25/G5 | H23: =H25/H5 | I23: =I25/I5 | J23: =J25/J5 | K23: =K25/K5 | L23: =L25/L5 | M23: =M25/M5 | N23: =N25/N5 | ... AC23: =AC25/AC5
D24: VI 금액 | F24: 목표 | G24: =SUM(G28,G32) | H24: =SUM(H28,H32) | I24: =SUM(I28,I32) | J24: =SUM(J28,J32) | K24: =SUM(K28,K32) | L24: =SUM(L28,L32) | M24: =SUM(M28,M32) | N24: =SUM(N28,N32) | ... AC24: =SUM(AC28,AC32)
F25: 실적 | G25: =SUM(G29,G33) | H25: =SUM(H29,H33) | I25: =SUM(I29,I33) | J25: =SUM(J29,J33) | K25: =SUM(K29,K33) | L25: =SUM(L29,L33) | M25: =SUM(M29,M33) | N25: =SUM(N29,N33) | ... AC25: =SUM(AC29,AC33)
C26: 제품1 | D26: VI율 | F26: 목표 | G26: =G28/G6 | H26: =H28/H6 | I26: =I28/I6 | J26: =J28/J6 | K26: =K28/K6 | L26: =L28/L6 | M26: =M28/M6 | N26: =N28/N6 | ... AC26: =AC28/AC6
F27: 실적 | G27: =G29/G7 | H27: =H29/H7 | I27: =I29/I7 | J27: =J29/J7 | K27: =K29/K7 | L27: =L29/L7 | M27: =M29/M7 | N27: =N29/N7 | ... AC27: =AC29/AC7
D28: VI 금액 | F28: 목표 | G28: 537.72409 | H28: 537.72409 | I28: 537.72409 | J28: 537.72409 | K28: 537.72409 | L28: 537.72409 | M28: 431.94886 | N28: 431.94886 | O28: 431.94886 | P28: 431.94886 | Q28: 431.94886 | R28: 455.07452 | S28: 455.07452 | T28: 455.07452 | U28: 455.07452 | V28: 455.07452 | W28: 455.07452 | X28: 757.73296 | Y28: 757.73296 | Z28: 757.73296 | AA28: 757.73296 | AB28: 757.73296 | AC28: 757.73296
F29: 실적 | G29: 312.52429 | H29: 607.14217 | I29: 607.14217 | J29: 304.13685 | K29: 304.13685 | L29: 607.14217 | M29: 361.34982 | N29: 483.686 | O29: 666.16353 | P29: 482.344 | Q29: 452.32886 | R29: 608.19899 | S29: 658.67256 | T29: 272.32751 | U29: 571.29539 | V29: 264.937 | W29: 264.937 | X29: 476.49903 | Y29: 213.04399 | Z29: 183.83662 | AA29: 183.83662 | AB29: 318.76641 | AC29: 183.83662
C30: 제품2 | D30: VI율 | F30: 목표 | G30: =G32/G8 | H30: =H32/H8 | I30: =I32/I8 | J30: =J32/J8 | K30: =K32/K8 | L30: =L32/L8 | M30: =M32/M8 | N30: =N32/N8 | ... AC30: =AC32/AC8
F31: 실적 | G31: =G33/G9 | H31: =H33/H9 | I31: =I33/I9 | J31: =J33/J9 | K31: =K33/K9 | L31: =L33/L9 | M31: =M33/M9 | N31: =N33/N9 | ... AC31: =AC33/AC9
D32: VI 금액 | F32: 목표 | G32: 21.851122 | H32: 21.851122 | I32: 21.851122 | J32: 21.851122 | K32: 21.851122 | L32: 21.851122 | M32: 32.390966 | N32: 32.390966 | O32: 32.390966 | P32: 32.390966 | Q32: 32.390966 | R32: 24.993993 | S32: 24.993993 | T32: 24.993993 | U32: 24.993993 | V32: 24.993993 | W32: 24.993993 | X32: 21.909611 | Y32: 21.909611 | Z32: 21.909611 | AA32: 21.909611 | AB32: 21.909611 | AC32: 21.909611
F33: 실적 | G33: 21.422172 | H33: 21.11276 | I33: 21.11276 | J33: 17.870585 | K33: 17.870585 | L33: 21.11276 | M33: 21.221203 | N33: 8.516 | O33: 15.648748 | P33: 13.372 | Q33: 12.572947 | R33: 17.523932 | S33: 24.473598 | T33: 32.291734 | U33: 27.145505 | V33: 16.647 | W33: 16.647 | X33: 9.0639145 | Y33: 12.389032 | Z33: 6.6462495 | AA33: 6.6462495 | AB33: 17.44816 | AC33: 6.6462495
B34: 시스템 미반영 | C34: 키친솔루션 | D34: VI율 | F34: 목표 | G34: =G36/G4 | H34: =H36/H4 | I34: =I36/I4 | J34: =J36/J4 | K34: =K36/K4 | L34: =L36/L4 | M34: =M36/M4 | N34: =N36/N4 | ... AC34: =AC36/AC4
F35: 실적 | G35: =G37/G5 | H35: =H37/H5 | I35: =I37/I5 | J35: =J37/J5 | K35: =K37/K5 | L35: =L37/L5 | M35: =M37/M5 | N35: =N37/N5 | ... AC35: =AC37/AC5
D36: VI 금액 | E36: 합계 | F36: 목표 | G36: =SUM(G46,G56) | H36: =SUM(H46,H56) | I36: =SUM(I46,I56) | J36: =SUM(J46,J56) | K36: =SUM(K46,K56) | L36: =SUM(L46,L56) | M36: =SUM(M46,M56) | N36: =SUM(N46,N56) | ... R36: =SUM(R46,R56) | S36: 189.89478 | T36: =SUM(T46,T56) | U36: =SUM(U46,U56) | V36: =SUM(V46,V56) | W36: =SUM(W46,W56) | X36: =SUM(X46,X56) | Y36: =SUM(Y46,Y56) | Z36: =SUM(Z46,Z56) | AA36: =SUM(AA46,AA56) | ... AC36: =SUM(AC46,AC56)
F37: 실적 | G37: =SUM(G47,G57) | H37: =SUM(H47,H57) | I37: =SUM(I47,I57) | J37: =SUM(J47,J57) | K37: =SUM(K47,K57) | L37: =SUM(L47,L57) | M37: =SUM(M47,M57) | N37: =SUM(N47,N57) | ... AC37: =SUM(AC47,AC57)
E38: 양산부품 | F38: 목표 | G38: =G48+G58 | H38: =H48+H58 | I38: =I48+I58 | J38: =J48+J58 | K38: =K48+K58 | L38: =L48+L58 | M38: =M48+M58 | N38: =N48+N58 | ... AC38: =AC48+AC58
F39: 실적 | G39: =G49+G59 | H39: =H49+H59 | I39: =I49+I59 | J39: =J49+J59 | K39: =K49+K59 | L39: =L49+L59 | M39: =M49+M59 | N39: =N49+N59 | ... AC39: =AC49+AC59
E40: 개발모델 | F40: 목표 | G40: =G50+G60 | H40: =H50+H60 | I40: =I50+I60 | J40: =J50+J60 | K40: =K50+K60 | L40: =L50+L60 | M40: =M50+M60 | N40: =N50+N60 | ... AC40: =AC50+AC60
F41: 실적 | G41: =G51+G61 | H41: =H51+H61 | I41: =I51+I61 | J41: =J51+J61 | K41: =K51+K61 | L41: =L51+L61 | M41: =M51+M61 | N41: =N51+N61 | ... AC41: =AC51+AC61
...

Sheet 가공비
F1: 계획환율 | G1: 1340 | H1: 1340 | I1: 1340 | J1: 1340 | K1: 1340 | L1: 1340 | M1: 1340 | N1: 1340 | O1: 1340 | P1: 1340 | Q1: 1340 | R1: 1340 | S1: 1340 | T1: 1340 | U1: 1340 | V1: 1340 | W1: 1340 | X1: 1340 | Y1: 1340 | Z1: 1340 | AA1: 1340 | AB1: 1340 | AC1: 1340
F2: 실적환율 | G2: 1454.6258 | H2: 1454.6258 | I2: 1454.6258 | J2: 1454.6258 | K2: 1454.6258 | L2: 1454.6258 | M2: 1450 | N2: 1450 | O2: 1450 | P2: 1450 | Q2: 1450 | R2: 1450 | S2: 1440 | T2: 1440 | U2: 1487.63 | V2: 1480 | W2: 1480 | X2: 1480 | Y2: 1480 | Z2: 1488.4613 | AA2: 1488.4613 | AB2: 1488.4613 | AC2: 1488.4613
G4: 1월 | M4: 2월 | R4: 3월 | X4: 4월 | AD4: 5월 | AK4: 6월 | AQ4: 7월 | AW4: 8월 | BD4: 9월 | BJ4: 10월 | BP4: 11월 | BU4: 12월
G5: 실적 | H5: W1 | I5: W2 | J5: W3 | K5: W4 | L5: W5 | M5: 실적 | N5: W6 | O5: W7 | P5: W8 | Q5: W9 | R5: 실적 | S5: W10 | T5: W11 | U5: W12 | V5: W13 | W5: W14 | X5: 실적 | Y5: W14 | Z5: W15 | AA5: W16 | AB5: W17 | AC5: W18 | AD5: 실적 | AE5: W18 | AF5: W19 | AG5: W20 | AH5: W21 | AI5: W22 | AJ5: W23 | AK5: 실적 | AL5: W23 | AM5: W24 | AN5: W25 | AO5: W26 | AP5: W27 | AQ5: 실적 | AR5: W27 | AS5: W28 | AT5: W29 | AU5: W30 | AV5: W31 | AW5: 실적 | AX5: W31 | AY5: W32 | AZ5: W33 | BA5: W34 | BB5: W35 | BC5: W36 | BD5: 실적 | BE5: W36 | BF5: W37 | BG5: W38 | BH5: W39 | BI5: W40 | BJ5: 실적 | BK5: W40 | BL5: W41 | BM5: W42 | BN5: W43 | BO5: W44 | BP5: 실적 | BQ5: W45 | BR5: W46 | BS5: W47 | BT5: W48 | BU5: 실적 | BV5: W49 | BW5: W50 | BX5: W51 | BY5: W52 | BZ5: W53
B6: 개선금액 | C6: 키친솔루션 | D6: 제품1 + 제품2 | F6: `26 목표 | G6: =G32*G1/10^2 | H6: =H32*H1/10^2 | I6: =I32*I1/10^2 | J6: =J32*J1/10^2 | K6: =K32*K1/10^2 | L6: =L32*L1/10^2 | M6: =M32*M1/10^2 | N6: =N32*N1/10^2 | ... AC6: =AC32*AC1/10^2
F7: `26 실적 | G7: =G33*G2/10^2 | H7: =H33*H2/10^2 | I7: =I33*I2/10^2 | J7: =J33*J2/10^2 | K7: =K33*K2/10^2 | L7: =L33*L2/10^2 | M7: =M33*M2/10^2 | N7: =N33*N2/10^2 | ... AC7: =AC33*AC2/10^2
C8: 제품1 | D8: 지역 합계 | F8: `26 목표 | G8: =G34*G1/10^2 | H8: =H34*H1/10^2 | I8: =I34*I1/10^2 | J8: =J34*J1/10^2 | K8: =K34*K1/10^2 | L8: =L34*L1/10^2 | M8: =M34*M1/10^2 | N8: =N34*N1/10^2 | ... AC8: =AC34*AC1/10^2
F9: `26 실적 | G9: =G35*G2/10^2 | H9: =H35*H2/10^2 | I9: =I35*I2/10^2 | J9: =J35*J2/10^2 | K9: =K35*K2/10^2 | L9: =L35*L2/10^2 | M9: =M35*M2/10^2 | N9: =N35*N2/10^2 | ... AC9: =AC35*AC2/10^2
D10: 지역1 | F10: `26 목표 | G10: =G36*G1/10^2 | H10: =H36*H1/10^2 | I10: =I36*I1/10^2 | J10: =J36*J1/10^2 | K10: =K36*K1/10^2 | L10: =L36*L1/10^2 | M10: =M36*M1/10^2 | N10: =N36*N1/10^2 | ... AC10: =AC36*AC1/10^2
F11: `26 실적 | G11: =G37*G2/10^2 | H11: =H37*H2/10^2 | I11: =I37*I2/10^2 | J11: =J37*J2/10^2 | K11: =K37*K2/10^2 | L11: =L37*L2/10^2 | M11: =M37*M2/10^2 | N11: =N37*N2/10^2 | ... AC11: =AC37*AC2/10^2
D12: 지역2 | F12: `26 목표 | G12: =G38*G1/10^2 | H12: =H38*H1/10^2 | I12: =I38*I1/10^2 | J12: =J38*J1/10^2 | K12: =K38*K1/10^2 | L12: =L38*L1/10^2 | M12: =M38*M1/10^2 | N12: =N38*N1/10^2 | ... T12: =T38*T1/10^2 | U12: 2.6091041 | V12: 1.7428603 | W12: =W38*W1/10^2 | X12: =X38*X1/10^2 | Y12: =Y38*Y1/10^2 | Z12: =Z38*Z1/10^2 | AA12: =AA38*AA1/10^2 | AB12: =AB38*AB1/10^2 | AC12: =AC38*AC1/10^2
F13: `26 실적 | G13: =G39*G2/10^2 | H13: =H39*H2/10^2 | I13: =I39*I2/10^2 | J13: =J39*J2/10^2 | K13: =K39*K2/10^2 | L13: =L39*L2/10^2 | M13: =M39*M2/10^2 | N13: =N39*N2/10^2 | ... T13: =T39*T2/10^2 | U13: 8.7096791 | V13: 6.0229064 | W13: =W39*W2/10^2 | X13: =X39*X2/10^2 | Y13: =Y39*Y2/10^2 | Z13: =Z39*Z2/10^2 | AA13: =AA39*AA2/10^2 | AB13: =AB39*AB2/10^2 | AC13: =AC39*AC2/10^2
D14: 지역3 | F14: `26 목표 | G14: =G40*G1/10^2 | H14: =H40*H1/10^2 | I14: =I40*I1/10^2 | J14: =J40*J1/10^2 | K14: =K40*K1/10^2 | L14: =L40*L1/10^2 | M14: =M40*M1/10^2 | N14: =N40*N1/10^2 | ... AC14: =AC40*AC1/10^2
F15: `26 실적 | G15: =G41*G2/10^2 | H15: =H41*H2/10^2 | I15: =I41*I2/10^2 | J15: =J41*J2/10^2 | K15: =K41*K2/10^2 | L15: =L41*L2/10^2 | M15: =M41*M2/10^2 | N15: =N41*N2/10^2 | ... AC15: =AC41*AC2/10^2
D16: 지역4 | F16: `26 목표 | G16: =G42*G1/10^2 | H16: =H42*H1/10^2 | I16: =I42*I1/10^2 | J16: =J42*J1/10^2 | K16: =K42*K1/10^2 | L16: =L42*L1/10^2 | M16: =M42*M1/10^2 | N16: =N42*N1/10^2 | ... AC16: =AC42*AC1/10^2
F17: `26 실적 | G17: =G43*G2/10^2 | H17: =H43*H2/10^2 | I17: =I43*I2/10^2 | J17: =J43*J2/10^2 | K17: =K43*K2/10^2 | L17: =L43*L2/10^2 | M17: =M43*M2/10^2 | N17: =N43*N2/10^2 | ... AC17: =AC43*AC2/10^2
D18: 지역5 | F18: `26 목표 | G18: =G44*G1/10^2 | H18: =H44*H1/10^2 | I18: =I44*I1/10^2 | J18: =J44*J1/10^2 | K18: =K44*K1/10^2 | L18: =L44*L1/10^2 | M18: =M44*M1/10^2 | N18: =N44*N1/10^2 | ... AC18: =AC44*AC1/10^2
F19: `26 실적 | G19: =G45*G2/10^2 | H19: =H45*H2/10^2 | I19: =I45*I2/10^2 | J19: =J45*J2/10^2 | K19: =K45*K2/10^2 | L19: =L45*L2/10^2 | M19: =M45*M2/10^2 | N19: =N45*N2/10^2 | ... AC19: =AC45*AC2/10^2
D20: 지역6 | F20: `26 목표 | G20: =G46*G1/10^2 | H20: =H46*H1/10^2 | I20: =I46*I1/10^2 | J20: =J46*J1/10^2 | K20: =K46*K1/10^2 | L20: =L46*L1/10^2 | M20: =M46*M1/10^2 | N20: =N46*N1/10^2 | ... AC20: =AC46*AC1/10^2
F21: `26 실적 | G21: =G47*G2/10^2 | H21: =H47*H2/10^2 | I21: =I47*I2/10^2 | J21: =J47*J2/10^2 | K21: =K47*K2/10^2 | L21: =L47*L2/10^2 | M21: =M47*M2/10^2 | N21: =N47*N2/10^2 | ... AC21: =AC47*AC2/10^2
D22: 지역7 | F22: `26 목표 | G22: =G48*G1/10^2 | H22: =H48*H1/10^2 | I22: =I48*I1/10^2 | J22: =J48*J1/10^2 | K22: =K48*K1/10^2 | L22: =L48*L1/10^2 | M22: =M48*M1/10^2 | N22: =N48*N1/10^2 | ... AC22: =AC48*AC1/10^2
F23: `26 실적 | G23: =G49*G2/10^2 | H23: =H49*H2/10^2 | I23: =I49*I2/10^2 | J23: =J49*J2/10^2 | K23: =K49*K2/10^2 | L23: =L49*L2/10^2 | M23: =M49*M2/10^2 | N23: =N49*N2/10^2 | ... AC23: =AC49*AC2/10^2
D24: 지역8 | F24: `26 목표 | G24: =G50*G1/10^2 | H24: =H50*H1/10^2 | I24: =I50*I1/10^2 | J24: =J50*J1/10^2 | K24: =K50*K1/10^2 | L24: =L50*L1/10^2 | M24: =M50*M1/10^2 | N24: =N50*N1/10^2 | ... Q24: =Q50*Q1/10^2 | R24: =R50*R$1/10^2 | S24: =S50*S$1/10^2 | T24: =T50*T$1/10^2 | U24: =U50*U$1/10^2 | V24: =V50*V$1/10^2 | W24: =W50*W$1/10^2 | X24: =X50*X$1/10^2 | Y24: =Y50*Y$1/10^2 | ... AC24: =AC50*AC$1/10^2
F25: `26 실적 | G25: =G51*G2/10^2 | H25: =H51*H2/10^2 | I25: =I51*I2/10^2 | J25: =J51*J2/10^2 | K25: =K51*K2/10^2 | L25: =L51*L2/10^2 | M25: =M51*M2/10^2 | N25: =N51*N2/10^2 | ... Q25: =Q51*Q2/10^2 | R25: =R51*R$2/10^2 | S25: =S51*S$2/10^2 | T25: =T51*T$2/10^2 | U25: =U51*U$2/10^2 | V25: =V51*V$2/10^2 | W25: =W51*W$2/10^2 | X25: =X51*X$2/10^2 | Y25: =Y51*Y$2/10^2 | ... AC25: =AC51*AC$2/10^2
C26: 제품2 | D26: 지역 합계 | F26: `26 목표 | G26: =G52*G1/10^2 | H26: =H52*H1/10^2 | I26: =I52*I1/10^2 | J26: =J52*J1/10^2 | K26: =K52*K1/10^2 | L26: =L52*L1/10^2 | M26: =M52*M1/10^2 | N26: =N52*N1/10^2 | ... AC26: =AC52*AC1/10^2
F27: `26 실적 | G27: =G53*G2/10^2 | H27: =H53*H2/10^2 | I27: =I53*I2/10^2 | J27: =J53*J2/10^2 | K27: =K53*K2/10^2 | L27: =L53*L2/10^2 | M27: =M53*M2/10^2 | N27: =N53*N2/10^2 | ... AC27: =AC53*AC2/10^2
D28: 지역1 | F28: `26 목표 | G28: =G54*G1/10^2 | H28: =H54*H1/10^2 | I28: =I54*I1/10^2 | J28: =J54*J1/10^2 | K28: =K54*K1/10^2 | L28: =L54*L1/10^2 | M28: =M54*M1/10^2 | N28: =N54*N1/10^2 | ... AC28: =AC54*AC1/10^2
F29: `26 실적 | G29: =G55*G2/10^2 | H29: =H55*H2/10^2 | I29: =I55*I2/10^2 | J29: =J55*J2/10^2 | K29: =K55*K2/10^2 | L29: =L55*L2/10^2 | M29: =M55*M2/10^2 | N29: =N55*N2/10^2 | ... AC29: =AC55*AC2/10^2
D30: 지역3 | F30: `26 목표 | G30: =G56*G1/10^2 | H30: =H56*H1/10^2 | I30: =I56*I1/10^2 | J30: =J56*J1/10^2 | K30: =K56*K1/10^2 | L30: =L56*L1/10^2 | M30: =M56*M1/10^2 | N30: =N56*N1/10^2 | ... Q30: =Q56*Q1/10^2 | R30: =R56*R$1/10^2 | S30: =S56*S$1/10^2 | T30: =T56*T$1/10^2 | U30: =U56*U$1/10^2 | V30: =V56*V$1/10^2 | W30: =W56*W$1/10^2 | X30: =X56*X$1/10^2 | Y30: =Y56*Y$1/10^2 | ... AC30: =AC56*AC$1/10^2
F31: `26 실적 | G31: =G57*G2/10^2 | H31: =H57*H2/10^2 | I31: =I57*I2/10^2 | J31: =J57*J2/10^2 | K31: =K57*K2/10^2 | L31: =L57*L2/10^2 | M31: =M57*M2/10^2 | N31: =N57*N2/10^2 | ... Q31: =Q57*Q2/10^2 | R31: =R57*R$2/10^2 | S31: =S57*S$2/10^2 | T31: =T57*T$2/10^2 | U31: =U57*U$2/10^2 | V31: =V57*V$2/10^2 | W31: =W57*W$2/10^2 | X31: =X57*X$2/10^2 | Y31: =Y57*Y$2/10^2 | ... AC31: =AC57*AC$2/10^2
B32: 개선금액 (M$) | C32: 키친솔루션 | D32: 제품1 + 제품2 | F32: `26 목표 | G32: =(G58-G59)*G62 | H32: =(H58-H59)*H62 | I32: =(I58-I59)*I62 | J32: =(J58-J59)*J62 | K32: =(K58-K59)*K62 | L32: =(L58-L59)*L62 | M32: =(M58-M59)*M62 | N32: =(N58-N59)*N62 | ... AC32: =(AC58-AC59)*AC62
F33: `26 실적 | G33: =(G58-G60)*G63 | H33: =(H58-H60)*H63 | I33: =(I58-I60)*I63 | J33: =(J58-J60)*J63 | K33: =(K58-K60)*K63 | L33: =(L58-L60)*L63 | M33: =(M58-M60)*M63 | N33: =(N58-N60)*N63 | ... AC33: =(AC58-AC60)*AC63
C34: 제품1 | D34: 지역 합계 | F34: `26 목표 | G34: =(G67-G68)*G71 | H34: =(H67-H68)*H71 | I34: =(I67-I68)*I71 | J34: =(J67-J68)*J71 | K34: =(K67-K68)*K71 | L34: =(L67-L68)*L71 | M34: =(M67-M68)*M71 | N34: =(N67-N68)*N71 | ... AC34: =(AC67-AC68)*AC71
F35: `26 실적 | G35: =(G67-G69)*G72 | H35: =(H67-H69)*H72 | I35: =(I67-I69)*I72 | J35: =(J67-J69)*J72 | K35: =(K67-K69)*K72 | L35: =(L67-L69)*L72 | M35: =(M67-M69)*M72 | N35: =(N67-N69)*N72 | ... AC35: =(AC67-AC69)*AC72
D36: 지역1 | F36: `26 목표 | G36: =(G76-G77)*G80 | H36: =(H76-H77)*H80 | I36: =(I76-I77)*I80 | J36: =(J76-J77)*J80 | K36: =(K76-K77)*K80 | L36: =(L76-L77)*L80 | M36: =(M76-M77)*M80 | N36: =(N76-N77)*N80 | ... AC36: =(AC76-AC77)*AC80
F37: `26 실적 | G37: =($G$76-G78)*G81 | H37: =($G$76-H78)*H81 | I37: =($G$76-I78)*I81 | J37: =($G$76-J78)*J81 | K37: =($G$76-K78)*K81 | L37: =($G$76-L78)*L81 | M37: =($G$76-M78)*M81 | N37: =($G$76-N78)*N81 | ... Q37: =($G$76-Q78)*Q81 | R37: =(R76-R78)*R81 | S37: =(S76-S78)*S81 | T37: =(T76-T78)*T81 | U37: =(U76-U78)*U81 | V37: =(V76-V78)*V81 | W37: =(W76-W78)*W81 | X37: =(X76-X78)*X81 | Y37: =(Y76-Y78)*Y81 | ... AC37: =(AC76-AC78)*AC81
D38: 지역2 | F38: `26 목표 | G38: =(G85-G86)*G89 | H38: =(H85-H86)*H89 | I38: =(I85-I86)*I89 | J38: =(J85-J86)*J89 | K38: =(K85-K86)*K89 | L38: =(L85-L86)*L89 | M38: =(M85-M86)*M89 | N38: =(N85-N86)*N89 | ... AC38: =(AC85-AC86)*AC89
F39: `26 실적 | G39: =(G85-G87)*G90 | H39: =(H85-H87)*H90 | I39: =(I85-I87)*I90 | J39: =(J85-J87)*J90 | K39: =(K85-K87)*K90 | L39: =(L85-L87)*L90 | M39: =(M85-M87)*M90 | N39: =(N85-N87)*N90 | ... AC39: =(AC85-AC87)*AC90
D40: 지역3 | F40: `26 목표 | G40: =(G94-G95)*G98 | H40: =(H94-H95)*H98 | I40: =(I94-I95)*I98 | J40: =(J94-J95)*J98 | K40: =(K94-K95)*K98 | L40: =(L94-L95)*L98 | M40: =(M94-M95)*M98 | N40: =(N94-N95)*N98 | ... AC40: =(AC94-AC95)*AC98
F41: `26 실적 | G41: =(G94-G96)*G99 | H41: =(H94-H96)*H99 | I41: =(I94-I96)*I99 | J41: =(J94-J96)*J99 | K41: =(K94-K96)*K99 | L41: =(L94-L96)*L99 | M41: =(M94-M96)*M99 | N41: =(N94-N96)*N99 | ... AC41: =(AC94-AC96)*AC99
...

Sheet 물류비
D1: 계획환율 | E1: 1350 | F1: 1350 | G1: 1350 | H1: 1350 | I1: 1350 | J1: 1350 | K1: 1350 | L1: 1350 | M1: 1350 | N1: 1350 | O1: 1350 | P1: 1350 | Q1: 1350 | R1: 1350 | S1: 1350 | T1: 1350 | U1: 1350 | V1: 1350 | W1: 1350 | X1: 1350 | Y1: 1350 | Z1: 1350 | AA1: 1350
D2: 실제환율 | E2: 1454.6258 | F2: 1454.6258 | G2: 1454.6258 | H2: 1460 | I2: 1460 | J2: 1447.7357 | K2: 1450 | L2: 1450 | M2: 1460 | N2: 1450 | O2: 1482.8516 | P2: 1440 | Q2: 1440 | R2: 1440 | S2: 1450 | T2: 1450 | U2: 1460 | V2: 1450 | W2: 1482.8516 | X2: 1440 | Y2: 1440 | Z2: 1450 | AA2: 1450
E4: 1월 | K4: 2월 | P4: 3월 | V4: 4월 | AB4: 5월 | AI4: 6월 | AO4: 7월 | AU4: 8월 | BB4: 9월 | BH4: 10월 | BN4: 11월 | BT4: 12월
E5: 실적 | F5: W1 | G5: W2 | H5: W3 | I5: W4 | J5: W5 | K5: 실적 | L5: W6 | M5: W7 | N5: W8 | O5: W9 | P5: 실적 | Q5: W10 | R5: W11 | S5: W12 | T5: W13 | U5: W14 | V5: 실적 | W5: W14 | X5: W15 | Y5: W16 | Z5: W17 | AA5: W18 | AB5: 실적 | AC5: W18 | AD5: W19 | AE5: W20 | AF5: W21 | AG5: W22 | AH5: W23 | AI5: 실적 | AJ5: W23 | AK5: W24 | AL5: W25 | AM5: W26 | AN5: W27 | AO5: 실적 | AP5: W27 | AQ5: W28 | AR5: W29 | AS5: W30 | AT5: W31 | AU5: 실적 | AV5: W31 | AW5: W32 | AX5: W33 | AY5: W34 | AZ5: W35 | BA5: W36 | BB5: 실적 | BC5: W36 | BD5: W37 | BE5: W38 | BF5: W39 | BG5: W40 | BH5: 실적 | BI5: W40 | BJ5: W41 | BK5: W42 | BL5: W43 | BM5: W44 | BN5: 실적 | BO5: W45 | BP5: W46 | BQ5: W47 | BR5: W48 | BS5: W49 | BT5: 실적 | BU5: W49 | BV5: W50 | BW5: W51 | BX5: W52 | BY5: W53
B6: 합계 | C6: 매출 | D6: `25 실적 | E6: 990.87306 | F6: 990.87306 | G6: 990.87306 | H6: 990.87306 | I6: 990.87306 | J6: 990.87306 | K6: 469.30086 | L6: 469.30086 | M6: 469.30086 | N6: 469.30086 | O6: 469.30086 | P6: 884.12491 | Q6: 884.12491 | R6: 884.12491 | S6: 884.12491 | T6: 884.12491 | U6: 884.12491 | V6: 428.98629 | W6: 428.98629 | X6: 428.98629 | Y6: 428.98629 | Z6: 428.98629 | AA6: 428.98629
D7: `26 목표 | E7: 799.29098 | F7: 799.29098 | G7: 799.29098 | H7: 799.29098 | I7: 799.29098 | J7: 799.29098 | K7: 672.18677 | L7: 672.18677 | M7: 672.18677 | N7: 672.18677 | O7: 672.18677 | P7: 1045.4408 | Q7: 1045.4408 | R7: 1045.4408 | S7: 1045.4408 | T7: 1045.4408 | U7: 1045.4408 | V7: 1205.0751 | W7: 1205.0751 | X7: 1205.0751 | Y7: 1205.0751 | Z7: 1205.0751 | AA7: 1205.0751
D8: `26 실적 | E8: 1074.0633 | F8: 805.17197 | G8: 805.17197 | H8: 805.17197 | I8: 805.17197 | J8: 805.17197 | K8: 1056.1486 | L8: 784.78953 | M8: 784.78953 | N8: 719.0363 | O8: 785.64002 | P8: 802.91878 | Q8: 448.14559 | R8: 448.14559 | S8: 448.14559 | T8: 1088.673 | U8: 448.14559 | V8: 756.45817 | W8: 668.04678 | X8: 668.04678 | Y8: 668.04678 | Z8: 668.04678 | AA8: 1017.8836
C9: 개선금액(원) | D9: `26 목표 | E9: =E11*E$1/10^2 | F9: =F11*F$1/10^2 | G9: =G11*G$1/10^2 | H9: =H11*H$1/10^2 | I9: =I11*I$1/10^2 | J9: =J11*J$1/10^2 | K9: =K11*K$1/10^2 | L9: =L11*L$1/10^2 | ... AA9: =AA11*AA$1/10^2
D10: `26 실적 | E10: =E12*E$2/10^2 | F10: =F12*F$2/10^2 | G10: =G12*G$2/10^2 | H10: =H12*H$2/10^2 | I10: =I12*I$2/10^2 | J10: =J12*J$2/10^2 | K10: =K12*K$2/10^2 | L10: =L12*L$2/10^2 | ... AA10: =AA12*AA$2/10^2
C11: 개선금액($) | D11: `26 목표 | E11: =(E13-E14)*E7 | F11: =(F13-F14)*F7 | G11: =(G13-G14)*G7 | H11: =(H13-H14)*H7 | I11: =(I13-I14)*I7 | J11: =(J13-J14)*J7 | K11: =(K13-K14)*K7 | L11: =(L13-L14)*L7 | ... AA11: =(AA13-AA14)*AA7
D12: `26 실적 | E12: =(E13-E15)*E8 | F12: =(F13-F15)*F8 | G12: =(G13-G15)*G8 | H12: =(H13-H15)*H8 | I12: =(I13-I15)*I8 | J12: =(J13-J15)*J8 | K12: =(K13-K15)*K8 | L12: =(L13-L15)*L8 | ... AA12: =(AA13-AA15)*AA8
C13: 물류비율 | D13: `25 실적 | E13: =E16/E6 | F13: =F16/F6 | G13: =G16/G6 | H13: =H16/H6 | I13: =I16/I6 | J13: =J16/J6 | K13: =K16/K6 | L13: =L16/L6 | ... AA13: =AA16/AA6
D14: `26 목표 | E14: =E17/E7 | F14: =F17/F7 | G14: =G17/G7 | H14: =H17/H7 | I14: =I17/I7 | J14: =J17/J7 | K14: =K17/K7 | L14: =L17/L7 | ... AA14: =AA17/AA7
D15: `26 실적 | E15: =E18/E8 | F15: =F18/F8 | G15: =G18/G8 | H15: =H18/H8 | I15: =I18/I8 | J15: =J18/J8 | K15: =K18/K8 | L15: =L18/L8 | ... AA15: =AA18/AA8
C16: 물류비 | D16: `25 실적 | E16: =SUM(E26,E36,E46,E56,E66) | F16: =SUM(F26,F36,F46,F56,F66) | G16: =SUM(G26,G36,G46,G56,G66) | H16: =SUM(H26,H36,H46,H56,H66) | I16: =SUM(I26,I36,I46,I56,I66) | J16: =SUM(J26,J36,J46,J56,J66) | K16: =SUM(K26,K36,K46,K56,K66) | L16: =SUM(L26,L36,L46,L56,L66) | ... AA16: =SUM(AA26,AA36,AA46,AA56,AA66)
D17: `26 목표 | E17: =SUM(E27,E37,E47,E57,E67) | F17: =SUM(F27,F37,F47,F57,F67) | G17: =SUM(G27,G37,G47,G57,G67) | H17: =SUM(H27,H37,H47,H57,H67) | I17: =SUM(I27,I37,I47,I57,I67) | J17: =SUM(J27,J37,J47,J57,J67) | K17: =SUM(K27,K37,K47,K57,K67) | L17: =SUM(L27,L37,L47,L57,L67) | ... AA17: =SUM(AA27,AA37,AA47,AA57,AA67)
D18: `26 실적 | E18: =SUM(E28,E38,E48,E58,E68) | F18: =SUM(F28,F38,F48,F58,F68) | G18: =SUM(G28,G38,G48,G58,G68) | H18: =SUM(H28,H38,H48,H58,H68) | I18: =SUM(I28,I38,I48,I58,I68) | J18: =SUM(J28,J38,J48,J58,J68) | K18: =SUM(K28,K38,K48,K58,K68) | L18: =SUM(L28,L38,L48,L58,L68) | ... AA18: =SUM(AA28,AA38,AA48,AA58,AA68)
B19: 해상 | C19: 개선금액(원) | D19: `26 목표 | E19: =E21*E$1/10^2 | F19: =F21*F$1/10^2 | G19: =G21*G$1/10^2 | H19: =H21*H$1/10^2 | I19: =I21*I$1/10^2 | J19: =J21*J$1/10^2 | K19: =K21*K$1/10^2 | L19: =L21*L$1/10^2 | ... AA19: =AA21*AA$1/10^2
D20: `26 실적 | E20: =E22*E$2/10^2 | F20: =F22*F$2/10^2 | G20: =G22*G$2/10^2 | H20: =H22*H$2/10^2 | I20: =I22*I$2/10^2 | J20: =J22*J$2/10^2 | K20: =K22*K$2/10^2 | L20: =L22*L$2/10^2 | ... AA20: =AA22*AA$2/10^2
C21: 개선금액($) | D21: `26 목표 | E21: =(E23-E24)*E7 | F21: =(F23-F24)*F7 | G21: =(G23-G24)*G7 | H21: =(H23-H24)*H7 | I21: =(I23-I24)*I7 | J21: =(J23-J24)*J7 | K21: =(K23-K24)*K7 | L21: =(L23-L24)*L7 | ... AA21: =(AA23-AA24)*AA7
D22: `26 실적 | E22: =(E23-E25)*E8 | F22: =(F23-F25)*F8 | G22: =(G23-G25)*G8 | H22: =(H23-H25)*H8 | I22: =(I23-I25)*I8 | J22: =(J23-J25)*J8 | K22: =(K23-K25)*K8 | L22: =(L23-L25)*L8 | ... AA22: =(AA23-AA25)*AA8
C23: 물류비율 | D23: `25 실적 | E23: =E26/E6 | F23: =F26/F6 | G23: =G26/G6 | H23: =H26/H6 | I23: =I26/I6 | J23: =J26/J6 | K23: =K26/K6 | L23: =L26/L6 | ... AA23: =AA26/AA6
D24: `26 목표 | E24: =E27/E7 | F24: =F27/F7 | G24: =G27/G7 | H24: =H27/H7 | I24: =I27/I7 | J24: =J27/J7 | K24: =K27/K7 | L24: =L27/L7 | ... AA24: =AA27/AA7
D25: `26 실적 | E25: =E28/E8 | F25: =F28/F8 | G25: =G28/G8 | H25: =H28/H8 | I25: =I28/I8 | J25: =J28/J8 | K25: =K28/K8 | L25: =L28/L8 | ... AA25: =AA28/AA8
C26: 물류비 | D26: `25 실적 | E26: 34.317279 | F26: 34.317279 | G26: 34.317279 | H26: 34.317279 | I26: 34.317279 | J26: 34.317279 | K26: 27.16303 | L26: 27.16303 | M26: 27.16303 | N26: 27.16303 | O26: 27.16303 | P26: 46.170446 | Q26: 46.170446 | R26: 46.170446 | S26: 46.170446 | T26: 46.170446 | U26: 46.170446 | V26: 22.07982 | W26: 22.07982 | X26: 22.07982 | Y26: 22.07982 | Z26: 22.07982 | AA26: 22.07982
D27: `26 목표 | E27: 35.525401 | F27: 35.525401 | G27: 35.525401 | H27: 35.525401 | I27: 35.525401 | J27: 35.525401 | K27: 15.68777 | L27: 15.68777 | M27: 15.68777 | N27: 15.68777 | O27: 15.68777 | P27: 23.234671 | Q27: 23.234671 | R27: 23.234671 | S27: 23.234671 | T27: 23.234671 | U27: 23.234671 | V27: 27.821701 | W27: 27.821701 | X27: 27.821701 | Y27: 27.821701 | Z27: 27.821701 | AA27: 27.821701
D28: `26 실적 | E28: 43.308148 | F28: 37.380411 | G28: 37.380411 | H28: 37.380411 | I28: 37.380411 | J28: 37.380411 | K28: 29.27355 | L28: 22.461225 | M28: 29.665054 | N28: 31.663867 | O28: 18.419 | P28: 35.610924 | Q28: 35.566277 | R28: 35.566277 | S28: 35.566277 | T28: 34.547537 | U28: 35.566277 | V28: 22.042961 | W28: 39.653132 | X28: 39.653132 | Y28: 39.653132 | Z28: 39.653132 | AA28: 40.567816
B29: 트럭 | C29: 개선금액(원) | D29: `26 목표 | E29: =E31*E$1/10^2 | F29: =F31*F$1/10^2 | G29: =G31*G$1/10^2 | H29: =H31*H$1/10^2 | I29: =I31*I$1/10^2 | J29: =J31*J$1/10^2 | K29: =K31*K$1/10^2 | L29: =L31*L$1/10^2 | ... AA29: =AA31*AA$1/10^2
D30: `26 실적 | E30: =E32*E$2/10^2 | F30: =F32*F$2/10^2 | G30: =G32*G$2/10^2 | H30: =H32*H$2/10^2 | I30: =I32*I$2/10^2 | J30: =J32*J$2/10^2 | K30: =K32*K$2/10^2 | L30: =L32*L$2/10^2 | ... AA30: =AA32*AA$2/10^2
C31: 개선금액($) | D31: `26 목표 | E31: =(E33-E34)*E7 | F31: =(F33-F34)*F7 | G31: =(G33-G34)*G7 | H31: =(H33-H34)*H7 | I31: =(I33-I34)*I7 | J31: =(J33-J34)*J7 | K31: =(K33-K34)*K7 | L31: =(L33-L34)*L7 | ... AA31: =(AA33-AA34)*AA7
D32: `26 실적 | E32: =(E33-E35)*E8 | F32: =(F33-F35)*F8 | G32: =(G33-G35)*G8 | H32: =(H33-H35)*H8 | I32: =(I33-I35)*I8 | J32: =(J33-J35)*J8 | K32: =(K33-K35)*K8 | L32: =(L33-L35)*L8 | ... AA32: =(AA33-AA35)*AA8
C33: 물류비율 | D33: `25 실적 | E33: =E36/E6 | F33: =F36/F6 | G33: =G36/G6 | H33: =H36/H6 | I33: =I36/I6 | J33: =J36/J6 | K33: =K36/K6 | L33: =L36/L6 | ... AA33: =AA36/AA6
D34: `26 목표 | E34: =E37/E7 | F34: =F37/F7 | G34: =G37/G7 | H34: =H37/H7 | I34: =I37/I7 | J34: =J37/J7 | K34: =K37/K7 | L34: =L37/L7 | ... AA34: =AA37/AA7
D35: `26 실적 | E35: =E38/E8 | F35: =F38/F8 | G35: =G38/G8 | H35: =H38/H8 | I35: =I38/I8 | J35: =J38/J8 | K35: =K38/K8 | L35: =L38/L8 | ... AA35: =AA38/AA8
C36: 물류비 | D36: `25 실적 | E36: 29.56399 | F36: 29.56399 | G36: 29.56399 | H36: 29.56399 | I36: 29.56399 | J36: 29.56399 | K36: 32.273222 | L36: 32.273222 | M36: 32.273222 | N36: 32.273222 | O36: 32.273222 | P36: 49.74129 | Q36: 49.74129 | R36: 49.74129 | S36: 49.74129 | T36: 49.74129 | U36: 49.74129 | V36: 56.000082 | W36: 56.000082 | X36: 56.000082 | Y36: 56.000082 | Z36: 56.000082 | AA36: 56.000082
D37: `26 목표 | E37: 50.457532 | F37: 50.457532 | G37: 50.457532 | H37: 50.457532 | I37: 50.457532 | J37: 50.457532 | K37: 34.586825 | L37: 34.586825 | M37: 34.586825 | N37: 34.586825 | O37: 34.586825 | P37: 41.257073 | Q37: 41.257073 | R37: 41.257073 | S37: 41.257073 | T37: 41.257073 | U37: 41.257073 | V37: 44.346318 | W37: 44.346318 | X37: 44.346318 | Y37: 44.346318 | Z37: 44.346318 | AA37: 44.346318
D38: `26 실적 | E38: 40.079517 | F38: 20.164111 | G38: 20.164111 | H38: 20.164111 | I38: 20.164111 | J38: 20.164111 | K38: 38.774181 | L38: 40.362321 | M38: 25.642278 | N38: 40.622388 | O38: 21.676166 | P38: 43.010166 | Q38: 32.181512 | R38: 32.181512 | S38: 32.181512 | T38: 50.646334 | U38: 32.181512 | V38: 27.65919 | W38: 43.03636 | X38: 43.03636 | Y38: 43.03636 | Z38: 43.03636 | AA38: 52.945092
B39: 철송 | C39: 개선금액(원) | D39: `26 목표 | E39: =E41*E$1/10^2 | F39: =F41*F$1/10^2 | G39: =G41*G$1/10^2 | H39: =H41*H$1/10^2 | I39: =I41*I$1/10^2 | J39: =J41*J$1/10^2 | K39: =K41*K$1/10^2 | L39: =L41*L$1/10^2 | ... AA39: =AA41*AA$1/10^2
D40: `26 실적 | E40: =E42*E$2/10^2 | F40: =F42*F$2/10^2 | G40: =G42*G$2/10^2 | H40: =H42*H$2/10^2 | I40: =I42*I$2/10^2 | J40: =J42*J$2/10^2 | K40: =K42*K$2/10^2 | L40: =L42*L$2/10^2 | ... AA40: =AA42*AA$2/10^2
C41: 개선금액($) | D41: `26 목표 | E41: =(E43-E44)*E7 | F41: =(F43-F44)*F7 | G41: =(G43-G44)*G7 | H41: =(H43-H44)*H7 | I41: =(I43-I44)*I7 | J41: =(J43-J44)*J7 | K41: =(K43-K44)*K7 | L41: =(L43-L44)*L7 | ... AA41: =(AA43-AA44)*AA7
...

Sheet 투자비
F2: 1월 | L2: 2월 | Q2: 3월 | W2: 4월 | AC2: 5월 | AJ2: 6월 | AP2: 7월 | AV2: 8월 | BC2: 9월 | BI2: 10월 | BO2: 11월 | BU2: 12월
F3: 실적 | G3: W1 | H3: W2 | I3: W3 | J3: W4 | K3: W5 | L3: 실적 | M3: W6 | N3: W7 | O3: W8 | P3: W9 | Q3: 실적 | R3: W10 | S3: W11 | T3: W12 | U3: W13 | V3: W14 | W3: 실적 | X3: W14 | Y3: W15 | Z3: W16 | AA3: W17 | AB3: W18 | AC3: 실적 | AD3: W18 | AE3: W19 | AF3: W20 | AG3: W21 | AH3: W22 | AI3: W23 | AJ3: 실적 | AK3: W23 | AL3: W24 | AM3: W25 | AN3: W26 | AO3: W27 | AP3: 실적 | AQ3: W27 | AR3: W28 | AS3: W29 | AT3: W30 | AU3: W31 | AV3: 실적 | AW3: W31 | AX3: W32 | AY3: W33 | AZ3: W34 | BA3: W35 | BB3: W36 | BC3: 실적 | BD3: W36 | BE3: W37 | BF3: W38 | BG3: W39 | BH3: W40 | BI3: 실적 | BJ3: W40 | BK3: W41 | BL3: W42 | BM3: W43 | BN3: W44 | BO3: 실적 | BP3: W45 | BQ3: W46 | BR3: W47 | BS3: W48 | BT3: W49 | BU3: 실적 | BV3: W49 | BW3: W50 | BX3: W51 | BY3: W52 | BZ3: W53
B4: Total | D4: 목표 | F4: =SUM(F8,F16) | G4: =SUM(G8,G16) | H4: =SUM(H8,H16) | I4: =SUM(I8,I16) | J4: =SUM(J8,J16) | K4: =SUM(K8,K16) | L4: =SUM(L8,L16) | M4: =SUM(M8,M16) | ... AB4: =SUM(AB8,AB16)
D5: 실적 | F5: =SUM(F12,F20) | G5: =SUM(G12,G20) | H5: =SUM(H12,H20) | I5: =SUM(I12,I20) | J5: =SUM(J12,J20) | K5: =SUM(K12,K20) | L5: =SUM(L12,L20) | M5: =SUM(M12,M20) | ... AB5: =SUM(AB12,AB20)
B6: 투자비 (설비) | C6: 제품1 | D6: 목표 | E6: Base | F6: 23.09 | G6: 23.09 | H6: 23.09 | I6: 23.09 | J6: 23.09 | K6: 23.09 | L6: 23.09 | M6: 23.09 | N6: 23.09 | O6: 23.09 | P6: 23.09 | Q6: 23.09 | R6: 23.09 | S6: 23.09 | T6: 23.09 | U6: 23.09 | V6: 23.09 | W6: 23.09 | X6: 23.09 | Y6: 23.09 | Z6: 23.09 | AA6: 23.09 | AB6: 23.09
E7: 발주금액 | F7: 22.01 | G7: 22.01 | H7: 22.01 | I7: 22.01 | J7: 22.01 | K7: 22.01 | L7: 22.01 | M7: 22.01 | N7: 22.01 | O7: 22.01 | P7: 22.01 | Q7: 22.01 | R7: 22.01 | S7: 22.01 | T7: 22.01 | U7: 22.01 | V7: 22.01 | W7: 22.01 | X7: 22.01 | Y7: 22.01 | Z7: 22.01 | AA7: 22.01 | AB7: 22.01
E8: 저감금액 | F8: =F6-F7 | G8: =G6-G7 | H8: =H6-H7 | I8: =I6-I7 | J8: =J6-J7 | K8: =K6-K7 | L8: =L6-L7 | M8: =M6-M7 | ... AB8: =AB6-AB7
E9: 저감율 | F9: =IFERROR(F8/F6,"") | G9: =IFERROR(G8/G6,"") | H9: =IFERROR(H8/H6,"") | I9: =IFERROR(I8/I6,"") | J9: =IFERROR(J8/J6,"") | K9: =IFERROR(K8/K6,"") | L9: =IFERROR(L8/L6,"") | M9: =IFERROR(M8/M6,"") | ... AB9: =IFERROR(AB8/AB6,"")
D10: 실적 | E10: Base | F10: 33.650726 | G10: 14.119224 | H10: 14.119224 | I10: 14.119224 | J10: 14.119224 | K10: 14.119224 | L10: 8.952104 | M10: 14.119224 | N10: 14.119224 | O10: 14.119224 | P10: 14.119224 | Q10: 33.650726 | R10: 14.119224 | S10: 14.119224 | T10: 14.119224 | U10: 14.119224 | V10: 14.119224 | W10: 33.650726 | X10: 14.119224 | Y10: 14.119224 | Z10: 14.119224 | AA10: 14.119224 | AB10: 14.119224
E11: 발주금액 | F11: 40.806567 | G11: 13.976576 | H11: 13.976576 | I11: 13.976576 | J11: 13.976576 | K11: 13.976576 | L11: 11.675561 | M11: 13.976576 | N11: 13.976576 | O11: 13.976576 | P11: 13.976576 | Q11: 40.806567 | R11: 13.976576 | S11: 13.976576 | T11: 13.976576 | U11: 13.976576 | V11: 13.976576 | W11: 40.806567 | X11: 13.976576 | Y11: 13.976576 | Z11: 13.976576 | AA11: 13.976576 | AB11: 13.976576
E12: 저감금액 | F12: =F10-F11 | G12: =G10-G11 | H12: =H10-H11 | I12: =I10-I11 | J12: =J10-J11 | K12: =K10-K11 | L12: =L10-L11 | M12: =M10-M11 | ... AB12: =AB10-AB11
E13: 저감율 | F13: =IFERROR(F12/F10,"") | G13: =IFERROR(G12/G10,"") | H13: =IFERROR(H12/H10,"") | I13: =IFERROR(I12/I10,"") | J13: =IFERROR(J12/J10,"") | K13: =IFERROR(K12/K10,"") | L13: =IFERROR(L12/L10,"") | M13: =IFERROR(M12/M10,"") | ... AB13: =IFERROR(AB12/AB10,"")
B14: 투자비 (금형) | C14: 제품1 + 제품2 | D14: 목표 | E14: Base | F14: =SUM(F22,F30) | G14: =SUM(G22,G30) | H14: =SUM(H22,H30) | I14: =SUM(I22,I30) | J14: =SUM(J22,J30) | K14: =SUM(K22,K30) | L14: =SUM(L22,L30) | M14: =SUM(M22,M30) | ... AB14: =SUM(AB22,AB30)
E15: 발주금액 | F15: =SUM(F23,F31) | G15: =SUM(G23,G31) | H15: =SUM(H23,H31) | I15: =SUM(I23,I31) | J15: =SUM(J23,J31) | K15: =SUM(K23,K31) | L15: =SUM(L23,L31) | M15: =SUM(M23,M31) | ... AB15: =SUM(AB23,AB31)
E16: 저감금액 | F16: =F14-F15 | G16: =G14-G15 | H16: =H14-H15 | I16: =I14-I15 | J16: =J14-J15 | K16: =K14-K15 | L16: =L14-L15 | M16: =M14-M15 | ... AB16: =AB14-AB15
E17: 저감율 | F17: =F16/F14 | G17: =G16/G14 | H17: =H16/H14 | I17: =I16/I14 | J17: =J16/J14 | K17: =K16/K14 | L17: =L16/L14 | M17: =M16/M14 | ... AB17: =AB16/AB14
D18: 실적 | E18: Base | F18: =SUM(F26,F34) | G18: =SUM(G26,G34) | H18: =SUM(H26,H34) | I18: =SUM(I26,I34) | J18: =SUM(J26,J34) | K18: =SUM(K26,K34) | L18: =SUM(L26,L34) | M18: =SUM(M26,M34) | ... AB18: =SUM(AB26,AB34)
E19: 발주금액 | F19: =SUM(F27,F35) | G19: =SUM(G27,G35) | H19: =SUM(H27,H35) | I19: =SUM(I27,I35) | J19: =SUM(J27,J35) | K19: =SUM(K27,K35) | L19: =SUM(L27,L35) | M19: =SUM(M27,M35) | ... AB19: =SUM(AB27,AB35)
E20: 저감금액 | F20: =F18-F19 | G20: =G18-G19 | H20: =H18-H19 | I20: =I18-I19 | J20: =J18-J19 | K20: =K18-K19 | L20: =L18-L19 | M20: =M18-M19 | ... AB20: =AB18-AB19
E21: 저감율 | F21: =F20/F18 | G21: =G20/G18 | H21: =H20/H18 | I21: =I20/I18 | J21: =J20/J18 | K21: =K20/K18 | L21: =L20/L18 | M21: =M20/M18 | ... AB21: =AB20/AB18
C22: 제품1 | D22: 목표 | E22: Base | F22: 90.012679 | G22: 90.012679 | H22: 90.012679 | I22: 90.012679 | J22: 90.012679 | K22: 90.012679 | L22: 67.676505 | M22: 67.676505 | N22: 67.676505 | O22: 67.676505 | P22: 67.676505 | Q22: 94.374656 | R22: 94.374656 | S22: 94.374656 | T22: 94.374656 | U22: 94.374656 | V22: 94.374656 | W22: 28.888039 | X22: 28.888039 | Y22: 28.888039 | Z22: 28.888039 | AA22: 28.888039 | AB22: 28.888039
E23: 발주금액 | F23: =F22-F24 | G23: =G22-G24 | H23: =H22-H24 | I23: =I22-I24 | J23: =J22-J24 | K23: =K22-K24 | L23: =L22-L24 | M23: =M22-M24 | ... AB23: =AB22-AB24
E24: 저감금액 | F24: 21.365528 | G24: 21.365528 | H24: 21.365528 | I24: 21.365528 | J24: 21.365528 | K24: 21.365528 | L24: 12.488623 | M24: 12.488623 | N24: 12.488623 | O24: 12.488623 | P24: 12.488623 | Q24: 8.793067 | R24: 8.793067 | S24: 8.793067 | T24: 8.793067 | U24: 8.793067 | V24: 8.793067 | W24: 2.5761836 | X24: 2.5761836 | Y24: 2.5761836 | Z24: 2.5761836 | AA24: 2.5761836 | AB24: 2.5761836
E25: 저감율 | F25: =F24/F22 | G25: =G24/G22 | H25: =H24/H22 | I25: =I24/I22 | J25: =J24/J22 | K25: =K24/K22 | L25: =L24/L22 | M25: =M24/M22 | ... AB25: =AB24/AB22
D26: 실적 | E26: Base | F26: 105.25449 | G26: 39.471596 | H26: 39.471596 | I26: 103.07188 | J26: 103.07188 | K26: 39.471596 | L26: 112.84152 | M26: 12.734455 | N26: 12.734455 | O26: 112.84152 | P26: 112.84152 | Q26: =U26 | R26: 90.527968 | S26: 51.388613 | T26: 78.073142 | U26: 78.073142 | V26: 78.073142 | W26: 35.472681 | X26: 6.935 | Y26: 32.873788 | Z26: 76.217636 | AA26: 76.217636 | AB26: 35.472681
E27: 발주금액 | F27: 46.143529 | G27: 64.907316 | H27: 64.907316 | I27: 93.710091 | J27: 93.710091 | K27: 64.907316 | L27: 68.277419 | M27: 11.931998 | N27: 11.931998 | O27: 68.277419 | P27: 68.277419 | Q27: =U27 | R27: 86.41451 | S27: 27.896837 | T27: 26.304242 | U27: 26.304242 | V27: 26.304242 | W27: 27.608224 | X27: 2.9290528 | Y27: 48.459616 | Z27: 21.965945 | AA27: 21.965945 | AB27: 27.608224
E28: 저감금액 | F28: =F26-F27 | G28: =G26-G27 | H28: =H26-H27 | I28: =I26-I27 | J28: =J26-J27 | K28: =K26-K27 | L28: =L26-L27 | M28: =M26-M27 | ... AB28: =AB26-AB27
E29: 저감율 | F29: =F28/F26 | G29: =G28/G26 | H29: =H28/H26 | I29: =I28/I26 | J29: =J28/J26 | K29: =K28/K26 | L29: =L28/L26 | M29: =M28/M26 | ... AB29: =AB28/AB26
C30: 제품2 | D30: 목표 | E30: Base | F30: 2.9822557 | G30: 2.9822557 | H30: 2.9822557 | I30: 2.9822557 | J30: 2.9822557 | K30: 2.9822557 | L30: 2.4766993 | M30: 2.4766993 | N30: 2.4766993 | O30: 2.4766993 | P30: 2.4766993 | Q30: 2.4740914 | R30: 2.4740914 | S30: 2.4740914 | T30: 2.4740914 | U30: 2.4740914 | V30: 2.4740914 | W30: 5.4077801 | X30: 5.4077801 | Y30: 5.4077801 | Z30: 5.4077801 | AA30: 5.4077801 | AB30: 5.4077801
E31: 발주금액 | F31: =F30-F32 | G31: =G30-G32 | H31: =H30-H32 | I31: =I30-I32 | J31: =J30-J32 | K31: =K30-K32 | L31: =L30-L32 | M31: =M30-M32 | ... AB31: =AB30-AB32
E32: 저감금액 | F32: 0.64849564 | G32: 0.64849564 | H32: 0.64849564 | I32: 0.64849564 | J32: 0.64849564 | K32: 0.64849564 | L32: 0.98788078 | M32: 0.98788078 | N32: 0.98788078 | O32: 0.98788078 | P32: 0.98788078 | Q32: 0.95 | R32: 0.95 | S32: 0.95 | T32: 0.95 | U32: 0.95 | V32: 0.95 | W32: 1.919127 | X32: 1.919127 | Y32: 1.919127 | Z32: 1.919127 | AA32: 1.919127 | AB32: 1.919127
E33: 저감율 | F33: =F32/F30 | G33: =G32/G30 | H33: =H32/H30 | I33: =I32/I30 | J33: =J32/J30 | K33: =K32/K30 | L33: =L32/L30 | M33: =M32/M30 | ... AB33: =AB32/AB30
D34: 실적 | E34: Base | F34: 3.3106561 | G34: 1.2014985 | H34: 1.2014985 | I34: 3.3106561 | J34: 3.3106561 | K34: 1.2014985 | L34: 2.9537467 | M34: 0.68946851 | N34: 0.68946851 | O34: 0.68946851 | P34: 2.9537467 | Q34: 3.3106561 | R34: 1.2014985 | S34: 1.2014985 | T34: 3.3106561 | U34: 3.3106561 | V34: 1.2014985 | W34: 3.3106561 | X34: 1.2014985 | Y34: 1.2014985 | Z34: 3.3106561 | AA34: 3.3106561 | AB34: 1.2014985
E35: 발주금액 | F35: 1.2018005 | G35: 0.59742609 | H35: 0.59742609 | I35: 1.2018005 | J35: 1.2018005 | K35: 0.59742609 | L35: 1.836603 | M35: 0.43948521 | N35: 0.43948521 | O35: 0.43948521 | P35: 1.836603 | Q35: 1.2018005 | R35: 0.59742609 | S35: 0.59742609 | T35: 1.2018005 | U35: 1.2018005 | V35: 0.59742609 | W35: 1.2018005 | X35: 0.59742609 | Y35: 0.59742609 | Z35: 1.2018005 | AA35: 1.2018005 | AB35: 0.59742609
E36: 저감금액 | F36: =F34-F35 | G36: =G34-G35 | H36: =H34-H35 | I36: =I34-I35 | J36: =J34-J35 | K36: =K34-K35 | L36: =L34-L35 | M36: =M34-M35 | ... AB36: =AB34-AB35
E37: 저감율 | F37: =F36/F34 | G37: =G36/G34 | H37: =H36/H34 | I37: =I36/I34 | J37: =J36/J34 | K37: =K36/K34 | L37: =L36/L34 | M37: =M36/M34 | ... AB37: =AB36/AB34

Sheet 매출_지역1
E2: 1월 | K2: 2월 | P2: 3월 | V2: 4월 | AB2: 5월 | AI2: 6월 | AO2: 7월 | AU2: 8월 | BB2: 9월 | BH2: 10월 | BN2: 11월 | BT2: 12월
E3: 실적 | F3: W1 | G3: W2 | H3: W3 | I3: W4 | J3: W5 | K3: 실적 | L3: W6 | M3: W7 | N3: W8 | O3: W9 | P3: 실적 | Q3: W10 | R3: W11 | S3: W12 | T3: W13 | U3: W14 | V3: 실적 | W3: W14 | X3: W15 | Y3: W16 | Z3: W17 | AA3: W18 | AB3: 실적 | AC3: W18 | AD3: W19 | AE3: W20 | AF3: W21 | AG3: W22 | AH3: W23 | AI3: 실적 | AJ3: W23 | AK3: W24 | AL3: W25 | AM3: W26 | AN3: W27 | AO3: 실적 | AP3: W27 | AQ3: W28 | AR3: W29 | AS3: W30 | AT3: W31 | AU3: 실적 | AV3: W31 | AW3: W32 | AX3: W33 | AY3: W34 | AZ3: W35 | BA3: W36 | BB3: 실적 | BC3: W36 | BD3: W37 | BE3: W38 | BF3: W39 | BG3: W40 | BH3: 실적 | BI3: W40 | BJ3: W41 | BK3: W42 | BL3: W43 | BM3: W44 | BN3: 실적 | BO3: W45 | BP3: W46 | BQ3: W47 | BR3: W48 | BS3: W49 | BT3: 실적 | BU3: W49 | BV3: W50 | BW3: W51 | BX3: W52 | BY3: W53
B4: 매출증분 + 원가인상 + 매출차감 | D4: `25 실적 | E4: =SUM(E10,E16,E22) | F4: =SUM(F10,F16,F22) | G4: =SUM(G10,G16,G22) | H4: =SUM(H10,H16,H22) | I4: =SUM(I10,I16,I22) | J4: =SUM(J10,J16,J22) | K4: =SUM(K10,K16,K22) | L4: =SUM(L10,L16,L22) | ... AA4: =SUM(AA10,AA16,AA22)
D5: `26 목표 | E5: =SUM(E11,E17,E23) | F5: =SUM(F11,F17,F23) | G5: =SUM(G11,G17,G23) | H5: =SUM(H11,H17,H23) | I5: =SUM(I11,I17,I23) | J5: =SUM(J11,J17,J23) | K5: =SUM(K11,K17,K23) | L5: =SUM(L11,L17,L23) | ... AA5: =SUM(AA11,AA17,AA23)
D6: `26 실적 | E6: =SUM(E12,E18,E24) | F6: =SUM(F12,F18,F24) | G6: =SUM(G12,G18,G24) | H6: =SUM(H12,H18,H24) | I6: =SUM(I12,I18,I24) | J6: =SUM(J12,J18,J24) | K6: =SUM(K12,K18,K24) | L6: =SUM(L12,L18,L24) | ... AA6: =SUM(AA12,AA18,AA24)
B7: 매출증분 | C7: 총매출($) | D7: `25 실적 | E7: 577.31058 | F7: 577.31058 | G7: 577.31058 | H7: 577.31058 | I7: 577.31058 | J7: 577.31058 | K7: 1147.6148 | L7: 1147.6148 | M7: 1147.6148 | N7: 1147.6148 | O7: 1147.6148 | P7: 486.99414 | Q7: 486.99414 | R7: 486.99414 | S7: 486.99414 | T7: 486.99414 | U7: 486.99414 | V7: 569.9721 | W7: 569.9721 | X7: 569.9721 | Y7: 569.9721 | Z7: 569.9721 | AA7: 569.9721
D8: `26 목표 | E8: 848.21128 | F8: 848.21128 | G8: 848.21128 | H8: 848.21128 | I8: 848.21128 | J8: 848.21128 | K8: 1035.8496 | L8: 1035.8496 | M8: 1035.8496 | N8: 1035.8496 | O8: 1035.8496 | P8: 785.27032 | Q8: 785.27032 | R8: 785.27032 | S8: 785.27032 | T8: 785.27032 | U8: 785.27032 | V8: 1380.1952 | W8: 1380.1952 | X8: 1380.1952 | Y8: 1380.1952 | Z8: 1380.1952 | AA8: 1380.1952
D9: `26 실적 | E9: 1178.7672 | F9: 970.17939 | G9: 970.17939 | H9: 970.17939 | I9: 970.17939 | J9: 593.01757 | K9: 668.11202 | L9: 1050.514 | M9: 986.125 | N9: 1050.514 | O9: 647.26444 | P9: 778.50562 | Q9: 815.9027 | R9: 861.88753 | S9: 768.31605 | T9: 790.05383 | U9: 790.05383 | V9: 1329.1848 | W9: 1336.3175 | X9: 568.44884 | Y9: 568.44884 | Z9: 568.44884 | AA9: 568.44884
C10: 개선금액(원) | D10: `25 실적 | E10: -244.76386 | F10: -244.76386 | G10: -244.76386 | H10: -244.76386 | I10: -244.76386 | J10: -244.76386 | K10: -140.12991 | L10: -140.12991 | M10: -140.12991 | N10: -140.12991 | O10: -140.12991 | P10: -77.375468 | Q10: -77.375468 | R10: -77.375468 | S10: -77.375468 | T10: -77.375468 | U10: -77.375468 | V10: -59.140674 | W10: -59.140674 | X10: -59.140674 | Y10: -59.140674 | Z10: -59.140674 | AA10: -59.140674
D11: `26 목표 | E11: 71.277701 | F11: 71.277701 | G11: 71.277701 | H11: 71.277701 | I11: 71.277701 | J11: 71.277701 | K11: 141.07196 | L11: 141.07196 | M11: 141.07196 | N11: 141.07196 | O11: 141.07196 | P11: 83.589888 | Q11: 83.589888 | R11: 83.589888 | S11: 83.589888 | T11: 83.589888 | U11: 83.589888 | V11: 177.04134 | W11: 177.04134 | X11: 177.04134 | Y11: 177.04134 | Z11: 177.04134 | AA11: 177.04134
D12: `26 실적 | E12: 84.101626 | F12: 211.54221 | G12: 211.54221 | H12: 211.54221 | I12: 211.54221 | J12: 207.63914 | K12: -28.732097 | L12: 54.57345 | M12: 64.381326 | N12: 54.57345 | O12: -5.6100112 | P12: -190.50454 | Q12: -140.25607 | R12: -175.67616 | S12: -129.57394 | T12: -108.62572 | U12: -108.62572 | V12: -381.50158 | W12: -98.994224 | X12: -208.57199 | Y12: -208.57199 | Z12: -208.57199 | AA12: -208.57199
B13: 판가인상 | C13: 판가인상률(%) | D13: `25 실적 | E13: 0.00775992 | F13: 0.00775992 | G13: 0.00775992 | H13: 0.00775992 | I13: 0.00775992 | J13: 0.00775992 | K13: 0.00886992 | L13: 0.00886992 | M13: 0.00886992 | N13: 0.00886992 | O13: 0.00886992 | P13: 0.00682432 | Q13: 0.00682432 | R13: 0.00682432 | S13: 0.00682432 | T13: 0.00682432 | U13: 0.00682432 | V13: 0.01408987 | W13: 0.01408987 | X13: 0.01408987 | Y13: 0.01408987 | Z13: 0.01408987 | AA13: 0.01408987
D14: `26 목표 | E14: 0.01430064 | F14: 0.01430064 | G14: 0.01430064 | H14: 0.01430064 | I14: 0.01430064 | J14: 0.01430064 | K14: 0.01809574 | L14: 0.01809574 | M14: 0.01809574 | N14: 0.01809574 | O14: 0.01809574 | P14: 0.01756349 | Q14: 0.01756349 | R14: 0.01756349 | S14: 0.01756349 | T14: 0.01756349 | U14: 0.01756349 | V14: 0.01784333 | W14: 0.01784333 | X14: 0.01784333 | Y14: 0.01784333 | Z14: 0.01784333 | AA14: 0.01784333
D15: `26 실적 | E15: 0.01434856 | F15: 0.02367701 | G15: 0.02367701 | H15: 0.02367701 | I15: 0.02367701 | J15: 0.02367701 | K15: 0.00617723 | L15: 0.01268975 | M15: 0.01132708 | N15: 0.01268975 | O15: 0.01132708 | P15: 0.01534085 | Q15: 0.02385566 | R15: 0.00870647 | S15: 0.00870647 | T15: 0.00870647 | U15: 0.00870647 | V15: 0.02677562 | W15: 0.01762525 | X15: 0.02527452 | Y15: 0.02527452 | Z15: 0.02527452 | AA15: 0.02527452
C16: 개선금액(원) | D16: `25 실적 | E16: 124.21237 | F16: 124.21237 | G16: 124.21237 | H16: 124.21237 | I16: 124.21237 | J16: 124.21237 | K16: 54.057726 | L16: 54.057726 | M16: 54.057726 | N16: 54.057726 | O16: 54.057726 | P16: 54.788784 | Q16: 54.788784 | R16: 54.788784 | S16: 54.788784 | T16: 54.788784 | U16: 54.788784 | V16: 189.01024 | W16: 189.01024 | X16: 189.01024 | Y16: 189.01024 | Z16: 189.01024 | AA16: 189.01024
D17: `26 목표 | E17: 360.0573 | F17: 360.0573 | G17: 360.0573 | H17: 360.0573 | I17: 360.0573 | J17: 360.0573 | K17: 226.6459 | L17: 226.6459 | M17: 226.6459 | N17: 226.6459 | O17: 226.6459 | P17: 181.77271 | Q17: 181.77271 | R17: 181.77271 | S17: 181.77271 | T17: 181.77271 | U17: 181.77271 | V17: 478.23494 | W17: 478.23494 | X17: 478.23494 | Y17: 478.23494 | Z17: 478.23494 | AA17: 478.23494
D18: `26 실적 | E18: 233.38592 | F18: 218.34253 | G18: 218.34253 | H18: 218.34253 | I18: 218.34253 | J18: 169.30938 | K18: 36.584044 | L18: 71.269285 | M18: 124.70383 | N18: 71.269285 | O18: 141.84756 | P18: 160.08725 | Q18: 322.25191 | R18: 101.93723 | S18: 101.93723 | T18: 101.93723 | U18: 101.93723 | V18: 318.58924 | W18: 247.77903 | X18: 392.697 | Y18: 392.697 | Z18: 392.697 | AA18: 392.697
B19: 매출차감 | C19: 총매출($) | D19: `25 실적 | E19: 0.0941759 | F19: 0.0941759 | G19: 0.0941759 | H19: 0.0941759 | I19: 0.0941759 | J19: 0.0941759 | K19: 0.16518594 | L19: 0.16518594 | M19: 0.16518594 | N19: 0.16518594 | O19: 0.16518594 | P19: 0.14079385 | Q19: 0.14079385 | R19: 0.14079385 | S19: 0.14079385 | T19: 0.14079385 | U19: 0.14079385 | V19: 0.21030877 | W19: 0.21030877 | X19: 0.21030877 | Y19: 0.21030877 | Z19: 0.21030877 | AA19: 0.21030877
D20: `26 목표 | E20: 0.12642729 | F20: 0.12642729 | G20: 0.12642729 | H20: 0.12642729 | I20: 0.12642729 | J20: 0.12642729 | K20: 0.19824717 | L20: 0.19824717 | M20: 0.19824717 | N20: 0.19824717 | O20: 0.19824717 | P20: 0.1609407 | Q20: 0.1609407 | R20: 0.1609407 | S20: 0.1609407 | T20: 0.1609407 | U20: 0.1609407 | V20: 0.18833571 | W20: 0.18833571 | X20: 0.18833571 | Y20: 0.18833571 | Z20: 0.18833571 | AA20: 0.18833571
D21: `26 실적 | E21: 0.16519114 | F21: 0.20941988 | G21: 0.20941988 | H21: 0.20941988 | I21: 0.20941988 | J21: 0.14702318 | K21: 0.19007101 | L21: 0.17437869 | M21: 0.19881892 | N21: 0.17437869 | O21: 0.17557706 | P21: 0.17948961 | Q21: 0.23775695 | R21: 0.14780275 | S21: 0.22693117 | T21: 0.2267732 | U21: 0.2267732 | V21: 0.19819191 | W21: 0.22312695 | X21: 0.16722078 | Y21: 0.16722078 | Z21: 0.16722078 | AA21: 0.16722078
C22: 개선금액(원) | D22: `25 실적 | E22: 142.169 | F22: 142.169 | G22: 142.169 | H22: 142.169 | I22: 142.169 | J22: 142.169 | K22: 27.996083 | L22: 27.996083 | M22: 27.996083 | N22: 27.996083 | O22: 27.996083 | P22: -122.13686 | Q22: -122.13686 | R22: -122.13686 | S22: -122.13686 | T22: -122.13686 | U22: -122.13686 | V22: -223.63237 | W22: -223.63237 | X22: -223.63237 | Y22: -223.63237 | Z22: -223.63237 | AA22: -223.63237
D23: `26 목표 | E23: -212.61567 | F23: -212.61567 | G23: -212.61567 | H23: -212.61567 | I23: -212.61567 | J23: -212.61567 | K23: -246.41764 | L23: -246.41764 | M23: -246.41764 | N23: -246.41764 | O23: -246.41764 | P23: -252.73207 | Q23: -252.73207 | R23: -252.73207 | S23: -252.73207 | T23: -252.73207 | U23: -252.73207 | V23: -184.84807 | W23: -184.84807 | X23: -184.84807 | Y23: -184.84807 | Z23: -184.84807 | AA23: -184.84807
D24: `26 실적 | E24: -633.31332 | F24: -666.04981 | G24: -666.04981 | H24: -666.04981 | I24: -666.04981 | J24: -346.96279 | K24: -173.96743 | L24: -121.80445 | M24: -74.622304 | N24: -121.80445 | O24: -48.342526 | P24: -313.81193 | Q24: -197.33953 | R24: -122.53111 | S24: -169.02915 | T24: -167.58434 | U24: -167.58434 | V24: -200.02258 | W24: -280.1129 | X24: -190.12859 | Y24: -190.12859 | Z24: -190.12859 | AA24: -190.12859
B25: 지역별 개선금액 | C25: 지역 합계 | D25: `26 목표 | E25: =SUM(E27,E29,E31,E33,E35,E37,E39,E41) | F25: =SUM(F27,F29,F31,F33,F35,F37,F39,F41) | G25: =SUM(G27,G29,G31,G33,G35,G37,G39,G41) | H25: =SUM(H27,H29,H31,H33,H35,H37,H39,H41) | I25: =SUM(I27,I29,I31,I33,I35,I37,I39,I41) | J25: =SUM(J27,J29,J31,J33,J35,J37,J39,J41) | K25: =SUM(K27,K29,K31,K33,K35,K37,K39,K41) | L25: =SUM(L27,L29,L31,L33,L35,L37,L39,L41) | ... AA25: =SUM(AA27,AA29,AA31,AA33,AA35,AA37,AA39,AA41)
D26: `26 실적 | E26: =SUM(E28,E30,E32,E34,E36,E38,E40,E42) | F26: =SUM(F28,F30,F32,F34,F36,F38,F40,F42) | G26: =SUM(G28,G30,G32,G34,G36,G38,G40,G42) | H26: =SUM(H28,H30,H32,H34,H36,H38,H40,H42) | I26: =SUM(I28,I30,I32,I34,I36,I38,I40,I42) | J26: =SUM(J28,J30,J32,J34,J36,J38,J40,J42) | K26: =SUM(K28,K30,K32,K34,K36,K38,K40,K42) | L26: -68.794 | M26: -77.534 | N26: -68.794 | O26: =SUM(O28,O30,O32,O34,O36,O38,O40,O42) | P26: =SUM(P28,P30,P32,P34,P36,P38,P40,P42) | Q26: =SUM(Q28,Q30,Q32,Q34,Q36,Q38,Q40,Q42) | R26: =SUM(R28,R30,R32,R34,R36,R38,R40,R42) | S26: =SUM(S28,S30,S32,S34,S36,S38,S40,S42) | T26: =SUM(T28,T30,T32,T34,T36,T38,T40,T42) | U26: =SUM(U28,U30,U32,U34,U36,U38,U40,U42) | V26: =SUM(V28,V30,V32,V34,V36,V38,V40,V42) | ... AA26: =SUM(AA28,AA30,AA32,AA34,AA36,AA38,AA40,AA42)
C27: 권역1 | D27: `26 목표 | E27: 126.5649 | F27: 126.5649 | G27: 126.5649 | H27: 126.5649 | I27: 126.5649 | J27: 126.5649 | K27: 261.86307 | L27: 261.86307 | M27: 261.86307 | N27: 261.86307 | O27: 261.86307 | P27: 173.91975 | Q27: 173.91975 | R27: 173.91975 | S27: 173.91975 | T27: 173.91975 | U27: 173.91975 | V27: 122.26577 | W27: 122.26577 | X27: 122.26577 | Y27: 122.26577 | Z27: 122.26577 | AA27: 122.26577
D28: `26 실적 | E28: -71.121694 | F28: 3.7770601 | G28: 3.7770601 | H28: 3.7770601 | I28: 3.7770601 | J28: 37.363863 | K28: 31.845746 | L28: 46.02 | M28: 142.56576 | N28: 46.02 | O28: 178.82997 | P28: -7.0070447 | Q28: 32.406975 | R28: -12.995787 | S28: -12.995787 | T28: -59.601324 | U28: -59.601324 | V28: -249.60082 | W28: -62.965608 | X28: -102.49119 | Y28: -102.49119 | Z28: -102.49119 | AA28: -102.49119
C29: 권역2 | D29: `26 목표 | E29: -66.537906 | F29: -66.537906 | G29: -66.537906 | H29: -66.537906 | I29: -66.537906 | J29: -66.537906 | K29: -63.806986 | L29: -63.806986 | M29: -63.806986 | N29: -63.806986 | O29: -63.806986 | P29: -41.844188 | Q29: -41.844188 | R29: -41.844188 | S29: -41.844188 | T29: -41.844188 | U29: -41.844188 | V29: -9.1454007 | W29: -9.1454007 | X29: -9.1454007 | Y29: -9.1454007 | Z29: -9.1454007 | AA29: -9.1454007
D30: `26 실적 | E30: -38.226911 | F30: -53.754286 | G30: -53.754286 | H30: -53.754286 | I30: -53.754286 | J30: -46.653985 | K30: -43.127437 | L30: -30.255 | M30: -108.55975 | N30: -30.255 | O30: -53.453015 | P30: -38.864843 | Q30: -32.795456 | R30: -59.461277 | S30: -59.461277 | T30: -44.91246 | U30: -44.91246 | V30: -13.556187 | W30: -11.453814 | X30: -39.012523 | Y30: -39.012523 | Z30: -39.012523 | AA30: -39.012523
